Audio service failed again, please 2025-09-12 00:11:46,519 - util.py[DEBUG]: Cloud-init v. 22.4.2 running 'init-local' at Fri, 12 Sep 2025 00:11:46 +0000. Up 12.67 seconds.
2025-09-12 00:11:46,519 - main.py[DEBUG]: No kernel command line url found.
2025-09-12 00:11:46,519 - main.py[DEBUG]: Closing stdin.
2025-09-12 00:11:46,538 - util.py[DEBUG]: Writing to /var/log/cloud-init.log - ab: [644] 0 bytes
2025-09-12 00:11:46,540 - util.py[DEBUG]: Changing the ownership of /var/log/cloud-init.log to 0:4
2025-09-12 00:11:46,541 - util.py[DEBUG]: Writing to /var/lib/cloud/data/python-version - wb: [644] 4 bytes
2025-09-12 00:11:46,543 - util.py[DEBUG]: Attempting to remove /var/lib/cloud/instance/boot-finished
2025-09-12 00:11:46,545 - handlers.py[DEBUG]: start: init-local/check-cache: attempting to read from cache [check]
2025-09-12 00:11:46,545 - util.py[DEBUG]: Reading from /var/lib/cloud/instance/obj.pkl (quiet=False)
2025-09-12 00:11:46,545 - stages.py[DEBUG]: no cache found
2025-09-12 00:11:46,545 - handlers.py[DEBUG]: finish: init-local/check-cache: SUCCESS: no cache found
2025-09-12 00:11:46,546 - util.py[DEBUG]: Attempting to remove /var/lib/cloud/instance
2025-09-12 00:11:46,556 - stages.py[DEBUG]: Using distro class <class 'cloudinit.distros.debian.Distro'>
2025-09-12 00:11:46,557 - __init__.py[DEBUG]: Looking for data source in: ['NoCloud', 'None'], via packages ['', 'cloudinit.sources'] that matches dependencies ['FILESYSTEM']
2025-09-12 00:11:46,564 - __init__.py[DEBUG]: Searching for local data source in: ['DataSourceNoCloud']
2025-09-12 00:11:46,564 - handlers.py[DEBUG]: start: init-local/search-NoCloud: searching for local data from DataSourceNoCloud
2025-09-12 00:11:46,564 - __init__.py[DEBUG]: Seeing if we can get any data from <class 'cloudinit.sources.DataSourceNoCloud.DataSourceNoCloud'>
2025-09-12 00:11:46,565 - __init__.py[DEBUG]: Update datasource metadata and network config due to events: boot-new-instance
2025-09-12 00:11:46,565 - dmi.py[DEBUG]: querying dmi data /sys/class/dmi/id/product_serial
2025-09-12 00:11:46,565 - dmi.py[DEBUG]: did not find /sys/class/dmi/id/product_serial
2025-09-12 00:11:46,565 - dmi.py[DEBUG]: dmidata is not supported on armv7l
2025-09-12 00:11:46,566 - util.py[DEBUG]: Reading from /var/lib/cloud/seed/nocloud/user-data (quiet=False)
2025-09-12 00:11:46,566 - util.py[DEBUG]: Reading from /var/lib/cloud/seed/nocloud/meta-data (quiet=False)
2025-09-12 00:11:46,566 - util.py[DEBUG]: Reading from /var/lib/cloud/seed/nocloud/vendor-data (quiet=False)
2025-09-12 00:11:46,566 - util.py[DEBUG]: Reading from /var/lib/cloud/seed/nocloud/network-config (quiet=False)
2025-09-12 00:11:46,566 - util.py[DEBUG]: Reading from /var/lib/cloud/seed/nocloud-net/user-data (quiet=False)
2025-09-12 00:11:46,567 - util.py[DEBUG]: Reading from /var/lib/cloud/seed/nocloud-net/meta-data (quiet=False)
2025-09-12 00:11:46,567 - util.py[DEBUG]: Reading from /var/lib/cloud/seed/nocloud-net/vendor-data (quiet=False)
2025-09-12 00:11:46,567 - util.py[DEBUG]: Reading from /var/lib/cloud/seed/nocloud-net/network-config (quiet=False)
2025-09-12 00:11:46,567 - subp.py[DEBUG]: Running command ['blkid', '-tTYPE=vfat', '-odevice'] with allowed return codes [0, 2] (shell=False, capture=True)
2025-09-12 00:11:46,655 - subp.py[DEBUG]: Running command ['blkid', '-tTYPE=iso9660', '-odevice'] with allowed return codes [0, 2] (shell=False, capture=True)
2025-09-12 00:11:46,678 - subp.py[DEBUG]: Running command ['blkid', '-tLABEL=CIDATA', '-odevice'] with allowed return codes [0, 2] (shell=False, capture=True)
2025-09-12 00:11:46,701 - subp.py[DEBUG]: Running command ['blkid', '-tLABEL=cidata', '-odevice'] with allowed return codes [0, 2] (shell=False, capture=True)
2025-09-12 00:11:46,724 - subp.py[DEBUG]: Running command ['blkid', '-tLABEL_FATBOOT=cidata', '-odevice'] with allowed return codes [0, 2] (shell=False, capture=True)
2025-09-12 00:11:46,747 - handlers.py[DEBUG]: finish: init-local/search-NoCloud: FAIL: no local data found from DataSourceNoCloud
2025-09-12 00:11:46,747 - util.py[WARNING]: Getting data from <class 'cloudinit.sources.DataSourceNoCloud.DataSourceNoCloud'> failed
2025-09-12 00:11:46,747 - util.py[DEBUG]: Getting data from <class 'cloudinit.sources.DataSourceNoCloud.DataSourceNoCloud'> failed
Traceback (most recent call last):
  File "/usr/lib/python3/dist-packages/cloudinit/url_helper.py", line 78, in read_file_or_url
    with open(file_path, "rb") as fp:
         ^^^^^^^^^^^^^^^^^^^^^
FileNotFoundError: [Errno 2] No such file or directory: '/boot/firmwaremeta-data'

The above exception was the direct cause of the following exception:

Traceback (most recent call last):
  File "/usr/lib/python3/dist-packages/cloudinit/sources/__init__.py", line 946, in find_source
    if s.update_metadata_if_supported(
       ^^^^^^^^^^^^^^^^^^^^^^^^^^^^^^^
  File "/usr/lib/python3/dist-packages/cloudinit/sources/__init__.py", line 828, in update_metadata_if_supported
    result = self.get_data()
             ^^^^^^^^^^^^^^^
  File "/usr/lib/python3/dist-packages/cloudinit/sources/__init__.py", line 373, in get_data
    return_value = self._get_data()
                   ^^^^^^^^^^^^^^^^
  File "/usr/lib/python3/dist-packages/cloudinit/sources/DataSourceNoCloud.py", line 173, in _get_data
    (md_seed, ud, vd) = util.read_seeded(seedfrom, timeout=None)
                        ^^^^^^^^^^^^^^^^^^^^^^^^^^^^^^^^^^^^^^^^
  File "/usr/lib/python3/dist-packages/cloudinit/util.py", line 987, in read_seeded
    md_resp = url_helper.read_file_or_url(
              ^^^^^^^^^^^^^^^^^^^^^^^^^^^^
  File "/usr/lib/python3/dist-packages/cloudinit/url_helper.py", line 84, in read_file_or_url
    raise UrlError(cause=e, code=code, headers=None, url=url) from e
cloudinit.url_helper.UrlError: [Errno 2] No such file or directory: '/boot/firmwaremeta-data'
2025-09-12 00:11:46,768 - main.py[DEBUG]: No local datasource found
2025-09-12 00:11:46,770 - util.py[DEBUG]: Reading from /sys/class/net/wlan0/address (quiet=False)
2025-09-12 00:11:46,771 - util.py[DEBUG]: Read 18 bytes from /sys/class/net/wlan0/address
2025-09-12 00:11:46,771 - util.py[DEBUG]: Reading from /sys/class/net/lo/address (quiet=False)
2025-09-12 00:11:46,771 - util.py[DEBUG]: Read 18 bytes from /sys/class/net/lo/address
2025-09-12 00:11:46,771 - util.py[DEBUG]: Reading from /sys/class/net/eth0/address (quiet=False)
2025-09-12 00:11:46,771 - util.py[DEBUG]: Read 18 bytes from /sys/class/net/eth0/address
2025-09-12 00:11:46,773 - util.py[DEBUG]: Reading from /sys/class/net/wlan0/name_assign_type (quiet=False)
2025-09-12 00:11:46,773 - util.py[DEBUG]: Reading from /sys/class/net/eth0/name_assign_type (quiet=False)
2025-09-12 00:11:46,773 - util.py[DEBUG]: Read 2 bytes from /sys/class/net/eth0/name_assign_type
2025-09-12 00:11:46,773 - __init__.py[DEBUG]: Found unstable nic names: ['wlan0', 'eth0']; calling udevadm settle
2025-09-12 00:11:46,774 - subp.py[DEBUG]: Running command ['udevadm', 'settle'] with allowed return codes [0] (shell=False, capture=True)
2025-09-12 00:11:46,787 - util.py[DEBUG]: Waiting for udev events to settle took 0.013 seconds
2025-09-12 00:11:46,788 - util.py[DEBUG]: Reading from /sys/class/net/wlan0/address (quiet=False)
2025-09-12 00:11:46,788 - util.py[DEBUG]: Read 18 bytes from /sys/class/net/wlan0/address
2025-09-12 00:11:46,788 - util.py[DEBUG]: Reading from /sys/class/net/wlan0/carrier (quiet=False)
2025-09-12 00:11:46,789 - __init__.py[DEBUG]: Interface has no carrier: wlan0
2025-09-12 00:11:46,789 - util.py[DEBUG]: Reading from /sys/class/net/wlan0/dormant (quiet=False)
2025-09-12 00:11:46,789 - util.py[DEBUG]: Reading from /sys/class/net/wlan0/operstate (quiet=False)
2025-09-12 00:11:46,789 - util.py[DEBUG]: Read 5 bytes from /sys/class/net/wlan0/operstate
2025-09-12 00:11:46,790 - util.py[DEBUG]: Reading from /sys/class/net/eth0/address (quiet=False)
2025-09-12 00:11:46,790 - util.py[DEBUG]: Read 18 bytes from /sys/class/net/eth0/address
2025-09-12 00:11:46,791 - util.py[DEBUG]: Reading from /sys/class/net/eth0/carrier (quiet=False)
2025-09-12 00:11:46,791 - __init__.py[DEBUG]: Interface has no carrier: eth0
2025-09-12 00:11:46,791 - util.py[DEBUG]: Reading from /sys/class/net/eth0/dormant (quiet=False)
2025-09-12 00:11:46,791 - util.py[DEBUG]: Reading from /sys/class/net/eth0/operstate (quiet=False)
2025-09-12 00:11:46,792 - util.py[DEBUG]: Read 5 bytes from /sys/class/net/eth0/operstate
2025-09-12 00:11:46,792 - util.py[DEBUG]: Reading from /sys/class/net/eth0/address (quiet=False)
2025-09-12 00:11:46,792 - util.py[DEBUG]: Read 18 bytes from /sys/class/net/eth0/address
2025-09-12 00:11:46,793 - util.py[DEBUG]: Reading from /sys/class/net/wlan0/address (quiet=False)
2025-09-12 00:11:46,794 - util.py[DEBUG]: Read 18 bytes from /sys/class/net/wlan0/address
2025-09-12 00:11:46,794 - util.py[DEBUG]: Reading from /sys/class/net/lo/address (quiet=False)
2025-09-12 00:11:46,794 - util.py[DEBUG]: Read 18 bytes from /sys/class/net/lo/address
2025-09-12 00:11:46,794 - util.py[DEBUG]: Reading from /sys/class/net/eth0/address (quiet=False)
2025-09-12 00:11:46,794 - util.py[DEBUG]: Read 18 bytes from /sys/class/net/eth0/address
2025-09-12 00:11:46,795 - util.py[DEBUG]: Reading from /sys/class/net/wlan0/name_assign_type (quiet=False)
2025-09-12 00:11:46,796 - util.py[DEBUG]: Reading from /sys/class/net/eth0/name_assign_type (quiet=False)
2025-09-12 00:11:46,796 - util.py[DEBUG]: Read 2 bytes from /sys/class/net/eth0/name_assign_type
2025-09-12 00:11:46,796 - __init__.py[DEBUG]: Found unstable nic names: ['wlan0', 'eth0']; calling udevadm settle
2025-09-12 00:11:46,796 - subp.py[DEBUG]: Running command ['udevadm', 'settle'] with allowed return codes [0] (shell=False, capture=True)
2025-09-12 00:11:46,809 - util.py[DEBUG]: Waiting for udev events to settle took 0.013 seconds
2025-09-12 00:11:46,810 - util.py[DEBUG]: Reading from /sys/class/net/wlan0/address (quiet=False)
2025-09-12 00:11:46,810 - util.py[DEBUG]: Read 18 bytes from /sys/class/net/wlan0/address
2025-09-12 00:11:46,811 - util.py[DEBUG]: Reading from /sys/class/net/wlan0/carrier (quiet=False)
2025-09-12 00:11:46,811 - __init__.py[DEBUG]: Interface has no carrier: wlan0
2025-09-12 00:11:46,811 - util.py[DEBUG]: Reading from /sys/class/net/wlan0/dormant (quiet=False)
2025-09-12 00:11:46,811 - util.py[DEBUG]: Reading from /sys/class/net/wlan0/operstate (quiet=False)
2025-09-12 00:11:46,812 - util.py[DEBUG]: Read 5 bytes from /sys/class/net/wlan0/operstate
2025-09-12 00:11:46,812 - util.py[DEBUG]: Reading from /sys/class/net/eth0/address (quiet=False)
2025-09-12 00:11:46,812 - util.py[DEBUG]: Read 18 bytes from /sys/class/net/eth0/address
2025-09-12 00:11:46,813 - util.py[DEBUG]: Reading from /sys/class/net/eth0/carrier (quiet=False)
2025-09-12 00:11:46,813 - __init__.py[DEBUG]: Interface has no carrier: eth0
2025-09-12 00:11:46,813 - util.py[DEBUG]: Reading from /sys/class/net/eth0/dormant (quiet=False)
2025-09-12 00:11:46,813 - util.py[DEBUG]: Reading from /sys/class/net/eth0/operstate (quiet=False)
2025-09-12 00:11:46,814 - util.py[DEBUG]: Read 5 bytes from /sys/class/net/eth0/operstate
2025-09-12 00:11:46,814 - util.py[DEBUG]: Reading from /sys/class/net/eth0/address (quiet=False)
2025-09-12 00:11:46,814 - util.py[DEBUG]: Read 18 bytes from /sys/class/net/eth0/address
2025-09-12 00:11:46,815 - util.py[DEBUG]: Reading from /sys/class/net/eth0/device/device (quiet=False)
2025-09-12 00:11:46,815 - util.py[DEBUG]: Reading from /sys/class/net/wlan0/addr_assign_type (quiet=False)
2025-09-12 00:11:46,815 - util.py[DEBUG]: Read 2 bytes from /sys/class/net/wlan0/addr_assign_type
2025-09-12 00:11:46,815 - util.py[DEBUG]: Reading from /sys/class/net/wlan0/uevent (quiet=False)
2025-09-12 00:11:46,816 - util.py[DEBUG]: Read 39 bytes from /sys/class/net/wlan0/uevent
2025-09-12 00:11:46,816 - util.py[DEBUG]: Reading from /sys/class/net/wlan0/address (quiet=False)
2025-09-12 00:11:46,816 - util.py[DEBUG]: Read 18 bytes from /sys/class/net/wlan0/address
2025-09-12 00:11:46,817 - __init__.py[DEBUG]: ovs-vsctl not in PATH; not detecting Open vSwitch interfaces
2025-09-12 00:11:46,817 - util.py[DEBUG]: Reading from /sys/class/net/wlan0/device/device (quiet=False)
2025-09-12 00:11:46,817 - util.py[DEBUG]: Read 7 bytes from /sys/class/net/wlan0/device/device
2025-09-12 00:11:46,818 - util.py[DEBUG]: Reading from /sys/class/net/lo/addr_assign_type (quiet=False)
2025-09-12 00:11:46,818 - util.py[DEBUG]: Read 2 bytes from /sys/class/net/lo/addr_assign_type
2025-09-12 00:11:46,818 - util.py[DEBUG]: Reading from /sys/class/net/lo/uevent (quiet=False)
2025-09-12 00:11:46,818 - util.py[DEBUG]: Read 23 bytes from /sys/class/net/lo/uevent
2025-09-12 00:11:46,819 - util.py[DEBUG]: Reading from /sys/class/net/lo/address (quiet=False)
2025-09-12 00:11:46,819 - util.py[DEBUG]: Read 18 bytes from /sys/class/net/lo/address
2025-09-12 00:11:46,819 - util.py[DEBUG]: Reading from /sys/class/net/lo/device/device (quiet=False)
2025-09-12 00:11:46,819 - util.py[DEBUG]: Reading from /sys/class/net/eth0/addr_assign_type (quiet=False)
2025-09-12 00:11:46,820 - util.py[DEBUG]: Read 2 bytes from /sys/class/net/eth0/addr_assign_type
2025-09-12 00:11:46,820 - util.py[DEBUG]: Reading from /sys/class/net/eth0/uevent (quiet=False)
2025-09-12 00:11:46,820 - util.py[DEBUG]: Read 25 bytes from /sys/class/net/eth0/uevent
2025-09-12 00:11:46,821 - util.py[DEBUG]: Reading from /sys/class/net/eth0/address (quiet=False)
2025-09-12 00:11:46,821 - util.py[DEBUG]: Read 18 bytes from /sys/class/net/eth0/address
2025-09-12 00:11:46,821 - util.py[DEBUG]: Reading from /sys/class/net/eth0/device/device (quiet=False)
2025-09-12 00:11:46,822 - util.py[DEBUG]: Reading from /sys/class/net/wlan0/type (quiet=False)
2025-09-12 00:11:46,822 - util.py[DEBUG]: Read 2 bytes from /sys/class/net/wlan0/type
2025-09-12 00:11:46,822 - util.py[DEBUG]: Reading from /sys/class/net/lo/type (quiet=False)
2025-09-12 00:11:46,822 - util.py[DEBUG]: Read 4 bytes from /sys/class/net/lo/type
2025-09-12 00:11:46,822 - util.py[DEBUG]: Reading from /sys/class/net/eth0/type (quiet=False)
2025-09-12 00:11:46,823 - util.py[DEBUG]: Read 2 bytes from /sys/class/net/eth0/type
2025-09-12 00:11:46,823 - networking.py[DEBUG]: net: all expected physical devices present
2025-09-12 00:11:46,823 - stages.py[DEBUG]: applying net config names for {'ethernets': {'eth0': {'dhcp4': True, 'set-name': 'eth0', 'match': {'macaddress': 'b8:27:eb:65:09:fc'}}}, 'version': 2}
2025-09-12 00:11:46,823 - util.py[DEBUG]: Reading from /sys/class/net/eth0/device/device (quiet=False)
2025-09-12 00:11:46,824 - util.py[DEBUG]: Reading from /sys/class/net/wlan0/addr_assign_type (quiet=False)
2025-09-12 00:11:46,824 - util.py[DEBUG]: Read 2 bytes from /sys/class/net/wlan0/addr_assign_type
2025-09-12 00:11:46,824 - util.py[DEBUG]: Reading from /sys/class/net/wlan0/uevent (quiet=False)
2025-09-12 00:11:46,824 - util.py[DEBUG]: Read 39 bytes from /sys/class/net/wlan0/uevent
2025-09-12 00:11:46,825 - util.py[DEBUG]: Reading from /sys/class/net/wlan0/address (quiet=False)
2025-09-12 00:11:46,825 - util.py[DEBUG]: Read 18 bytes from /sys/class/net/wlan0/address
2025-09-12 00:11:46,825 - util.py[DEBUG]: Reading from /sys/class/net/wlan0/device/device (quiet=False)
2025-09-12 00:11:46,825 - util.py[DEBUG]: Read 7 bytes from /sys/class/net/wlan0/device/device
2025-09-12 00:11:46,826 - util.py[DEBUG]: Reading from /sys/class/net/lo/addr_assign_type (quiet=False)
2025-09-12 00:11:46,826 - util.py[DEBUG]: Read 2 bytes from /sys/class/net/lo/addr_assign_type
2025-09-12 00:11:46,826 - util.py[DEBUG]: Reading from /sys/class/net/lo/uevent (quiet=False)
2025-09-12 00:11:46,826 - util.py[DEBUG]: Read 23 bytes from /sys/class/net/lo/uevent
2025-09-12 00:11:46,827 - util.py[DEBUG]: Reading from /sys/class/net/lo/address (quiet=False)
2025-09-12 00:11:46,827 - util.py[DEBUG]: Read 18 bytes from /sys/class/net/lo/address
2025-09-12 00:11:46,827 - util.py[DEBUG]: Reading from /sys/class/net/lo/device/device (quiet=False)
2025-09-12 00:11:46,827 - util.py[DEBUG]: Reading from /sys/class/net/eth0/addr_assign_type (quiet=False)
2025-09-12 00:11:46,827 - util.py[DEBUG]: Read 2 bytes from /sys/class/net/eth0/addr_assign_type
2025-09-12 00:11:46,828 - util.py[DEBUG]: Reading from /sys/class/net/eth0/uevent (quiet=False)
2025-09-12 00:11:46,828 - util.py[DEBUG]: Read 25 bytes from /sys/class/net/eth0/uevent
2025-09-12 00:11:46,828 - util.py[DEBUG]: Reading from /sys/class/net/eth0/address (quiet=False)
2025-09-12 00:11:46,829 - util.py[DEBUG]: Read 18 bytes from /sys/class/net/eth0/address
2025-09-12 00:11:46,829 - util.py[DEBUG]: Reading from /sys/class/net/eth0/device/device (quiet=False)
2025-09-12 00:11:46,829 - util.py[DEBUG]: Reading from /sys/class/net/wlan0/operstate (quiet=False)
2025-09-12 00:11:46,829 - util.py[DEBUG]: Read 5 bytes from /sys/class/net/wlan0/operstate
2025-09-12 00:11:46,830 - util.py[DEBUG]: Reading from /sys/class/net/lo/operstate (quiet=False)
2025-09-12 00:11:46,830 - util.py[DEBUG]: Read 8 bytes from /sys/class/net/lo/operstate
2025-09-12 00:11:46,830 - util.py[DEBUG]: Reading from /sys/class/net/eth0/operstate (quiet=False)
2025-09-12 00:11:46,830 - util.py[DEBUG]: Read 5 bytes from /sys/class/net/eth0/operstate
2025-09-12 00:11:46,831 - subp.py[DEBUG]: Running command ['ip', '-6', 'addr', 'show', 'permanent', 'scope', 'global'] with allowed return codes [0] (shell=False, capture=True)
2025-09-12 00:11:46,888 - subp.py[DEBUG]: Running command ['ip', '-4', 'addr', 'show'] with allowed return codes [0] (shell=False, capture=True)
2025-09-12 00:11:46,894 - __init__.py[DEBUG]: Detected interfaces {'wlan0': {'downable': True, 'device_id': '0xa9a6', 'driver': 'brcmfmac', 'mac': 'b8:27:eb:30:5c:a9', 'name': 'wlan0', 'up': False}, 'lo': {'downable': False, 'device_id': None, 'driver': None, 'mac': '00:00:00:00:00:00', 'name': 'lo', 'up': True}, 'eth0': {'downable': True, 'device_id': None, 'driver': 'lan78xx', 'mac': 'b8:27:eb:65:09:fc', 'name': 'eth0', 'up': False}}
2025-09-12 00:11:46,895 - __init__.py[DEBUG]: no work necessary for renaming of [['b8:27:eb:65:09:fc', 'eth0', 'lan78xx', None]]
2025-09-12 00:11:46,895 - stages.py[INFO]: Applying network configuration from fallback bringup=False: {'ethernets': {'eth0': {'dhcp4': True, 'set-name': 'eth0', 'match': {'macaddress': 'b8:27:eb:65:09:fc'}}}, 'version': 2}
2025-09-12 00:11:46,896 - util.py[DEBUG]: Writing to /run/cloud-init/sem/apply_network_config.once - wb: [644] 23 bytes
2025-09-12 00:11:46,899 - subp.py[DEBUG]: Running command ['systemctl', 'is-enabled', 'NetworkManager.service'] with allowed return codes [0] (shell=False, capture=True)
2025-09-12 00:11:46,985 - __init__.py[DEBUG]: Selected renderer 'network-manager' from priority list: None
2025-09-12 00:11:46,986 - util.py[DEBUG]: Reading from /sys/class/net/wlan0/addr_assign_type (quiet=False)
2025-09-12 00:11:46,986 - util.py[DEBUG]: Read 2 bytes from /sys/class/net/wlan0/addr_assign_type
2025-09-12 00:11:46,987 - util.py[DEBUG]: Reading from /sys/class/net/wlan0/uevent (quiet=False)
2025-09-12 00:11:46,987 - util.py[DEBUG]: Read 39 bytes from /sys/class/net/wlan0/uevent
2025-09-12 00:11:46,987 - util.py[DEBUG]: Reading from /sys/class/net/wlan0/address (quiet=False)
2025-09-12 00:11:46,988 - util.py[DEBUG]: Read 18 bytes from /sys/class/net/wlan0/address
2025-09-12 00:11:46,988 - util.py[DEBUG]: Reading from /sys/class/net/wlan0/device/device (quiet=False)
2025-09-12 00:11:46,988 - util.py[DEBUG]: Read 7 bytes from /sys/class/net/wlan0/device/device
2025-09-12 00:11:46,988 - util.py[DEBUG]: Reading from /sys/class/net/lo/addr_assign_type (quiet=False)
2025-09-12 00:11:46,989 - util.py[DEBUG]: Read 2 bytes from /sys/class/net/lo/addr_assign_type
2025-09-12 00:11:46,989 - util.py[DEBUG]: Reading from /sys/class/net/lo/uevent (quiet=False)
2025-09-12 00:11:46,989 - util.py[DEBUG]: Read 23 bytes from /sys/class/net/lo/uevent
2025-09-12 00:11:46,989 - util.py[DEBUG]: Reading from /sys/class/net/lo/address (quiet=False)
2025-09-12 00:11:46,990 - util.py[DEBUG]: Read 18 bytes from /sys/class/net/lo/address
2025-09-12 00:11:46,990 - util.py[DEBUG]: Reading from /sys/class/net/lo/device/device (quiet=False)
2025-09-12 00:11:46,990 - util.py[DEBUG]: Reading from /sys/class/net/eth0/addr_assign_type (quiet=False)
2025-09-12 00:11:46,990 - util.py[DEBUG]: Read 2 bytes from /sys/class/net/eth0/addr_assign_type
2025-09-12 00:11:46,991 - util.py[DEBUG]: Reading from /sys/class/net/eth0/uevent (quiet=False)
2025-09-12 00:11:46,991 - util.py[DEBUG]: Read 25 bytes from /sys/class/net/eth0/uevent
2025-09-12 00:11:46,991 - util.py[DEBUG]: Reading from /sys/class/net/eth0/address (quiet=False)
2025-09-12 00:11:46,992 - util.py[DEBUG]: Read 18 bytes from /sys/class/net/eth0/address
2025-09-12 00:11:46,992 - util.py[DEBUG]: Reading from /sys/class/net/eth0/device/device (quiet=False)
2025-09-12 00:11:46,992 - util.py[DEBUG]: Reading from /sys/class/net/wlan0/type (quiet=False)
2025-09-12 00:11:46,992 - util.py[DEBUG]: Read 2 bytes from /sys/class/net/wlan0/type
2025-09-12 00:11:46,993 - util.py[DEBUG]: Reading from /sys/class/net/lo/type (quiet=False)
2025-09-12 00:11:46,993 - util.py[DEBUG]: Read 4 bytes from /sys/class/net/lo/type
2025-09-12 00:11:46,993 - util.py[DEBUG]: Reading from /sys/class/net/eth0/type (quiet=False)
2025-09-12 00:11:46,993 - util.py[DEBUG]: Read 2 bytes from /sys/class/net/eth0/type
2025-09-12 00:11:46,993 - network_state.py[DEBUG]: v2(ethernets) -> v1(physical):
{'type': 'physical', 'mac_address': 'b8:27:eb:65:09:fc', 'name': 'eth0', 'match': {'macaddress': 'b8:27:eb:65:09:fc'}, 'subnets': [{'type': 'dhcp4'}]}
2025-09-12 00:11:47,002 - network_state.py[DEBUG]: v2_common: handling config:
{'eth0': {'dhcp4': True, 'set-name': 'eth0', 'match': {'macaddress': 'b8:27:eb:65:09:fc'}}}
2025-09-12 00:11:47,010 - util.py[DEBUG]: Writing to /etc/NetworkManager/system-connections/cloud-init-eth0.nmconnection - wb: [600] 273 bytes
2025-09-12 00:11:47,012 - __init__.py[DEBUG]: Not bringing up newly configured network interfaces
2025-09-12 00:11:47,013 - main.py[DEBUG]: [local] Exiting without datasource
2025-09-12 00:11:47,014 - atomic_helper.py[DEBUG]: Atomically writing to file /var/lib/cloud/data/status.json (via temporary file /var/lib/cloud/data/tmphnr7903s) - w: [644] 475 bytes/chars
2025-09-12 00:11:47,015 - util.py[DEBUG]: Reading from /proc/uptime (quiet=False)
2025-09-12 00:11:47,016 - util.py[DEBUG]: Read 12 bytes from /proc/uptime
2025-09-12 00:11:47,016 - util.py[DEBUG]: cloud-init mode 'init' took 0.690 seconds (0.69)
2025-09-12 00:11:47,016 - handlers.py[DEBUG]: finish: init-local: FAIL: searching for local datasources
2025-09-12 00:11:48,851 - util.py[DEBUG]: Cloud-init v. 22.4.2 running 'init' at Fri, 12 Sep 2025 00:11:48 +0000. Up 15.00 seconds.
2025-09-12 00:11:48,852 - main.py[DEBUG]: No kernel command line url found.
2025-09-12 00:11:48,852 - main.py[DEBUG]: Closing stdin.
2025-09-12 00:11:48,860 - util.py[DEBUG]: Writing to /var/log/cloud-init.log - ab: [644] 0 bytes
2025-09-12 00:11:48,862 - util.py[DEBUG]: Changing the ownership of /var/log/cloud-init.log to 0:4
2025-09-12 00:11:48,863 - subp.py[DEBUG]: Running command ['ip', '--json', 'addr'] with allowed return codes [0] (shell=False, capture=True)
2025-09-12 00:11:48,871 - subp.py[DEBUG]: Running command ['ip', '-o', 'route', 'list'] with allowed return codes [0] (shell=False, capture=True)
2025-09-12 00:11:48,876 - subp.py[DEBUG]: Running command ['ip', '--oneline', '-6', 'route', 'list', 'table', 'all'] with allowed return codes [0, 1] (shell=False, capture=True)
2025-09-12 00:11:48,887 - handlers.py[DEBUG]: start: init-network/check-cache: attempting to read from cache [trust]
2025-09-12 00:11:48,888 - util.py[DEBUG]: Reading from /var/lib/cloud/instance/obj.pkl (quiet=False)
2025-09-12 00:11:48,888 - stages.py[DEBUG]: no cache found
2025-09-12 00:11:48,888 - handlers.py[DEBUG]: finish: init-network/check-cache: SUCCESS: no cache found
2025-09-12 00:11:48,889 - util.py[DEBUG]: Attempting to remove /var/lib/cloud/instance
2025-09-12 00:11:48,895 - stages.py[DEBUG]: Using distro class <class 'cloudinit.distros.debian.Distro'>
2025-09-12 00:11:48,896 - __init__.py[DEBUG]: Looking for data source in: ['NoCloud', 'None'], via packages ['', 'cloudinit.sources'] that matches dependencies ['FILESYSTEM', 'NETWORK']
2025-09-12 00:11:48,901 - __init__.py[DEBUG]: Searching for network data source in: ['DataSourceNoCloudNet', 'DataSourceNone']
2025-09-12 00:11:48,901 - handlers.py[DEBUG]: start: init-network/search-NoCloudNet: searching for network data from DataSourceNoCloudNet
2025-09-12 00:11:48,902 - __init__.py[DEBUG]: Seeing if we can get any data from <class 'cloudinit.sources.DataSourceNoCloud.DataSourceNoCloudNet'>
2025-09-12 00:11:48,902 - __init__.py[DEBUG]: Update datasource metadata and network config due to events: boot-new-instance
2025-09-12 00:11:48,902 - dmi.py[DEBUG]: querying dmi data /sys/class/dmi/id/product_serial
2025-09-12 00:11:48,903 - dmi.py[DEBUG]: did not find /sys/class/dmi/id/product_serial
2025-09-12 00:11:48,903 - dmi.py[DEBUG]: dmidata is not supported on armv7l
2025-09-12 00:11:48,903 - util.py[DEBUG]: Reading from /var/lib/cloud/seed/nocloud/user-data (quiet=False)
2025-09-12 00:11:48,903 - util.py[DEBUG]: Reading from /var/lib/cloud/seed/nocloud/meta-data (quiet=False)
2025-09-12 00:11:48,903 - util.py[DEBUG]: Reading from /var/lib/cloud/seed/nocloud/vendor-data (quiet=False)
2025-09-12 00:11:48,904 - util.py[DEBUG]: Reading from /var/lib/cloud/seed/nocloud/network-config (quiet=False)
2025-09-12 00:11:48,904 - util.py[DEBUG]: Reading from /var/lib/cloud/seed/nocloud-net/user-data (quiet=False)
2025-09-12 00:11:48,904 - util.py[DEBUG]: Reading from /var/lib/cloud/seed/nocloud-net/meta-data (quiet=False)
2025-09-12 00:11:48,904 - util.py[DEBUG]: Reading from /var/lib/cloud/seed/nocloud-net/vendor-data (quiet=False)
2025-09-12 00:11:48,904 - util.py[DEBUG]: Reading from /var/lib/cloud/seed/nocloud-net/network-config (quiet=False)
2025-09-12 00:11:48,905 - subp.py[DEBUG]: Running command ['blkid', '-tTYPE=vfat', '-odevice'] with allowed return codes [0, 2] (shell=False, capture=True)
2025-09-12 00:11:48,936 - subp.py[DEBUG]: Running command ['blkid', '-tTYPE=iso9660', '-odevice'] with allowed return codes [0, 2] (shell=False, capture=True)
2025-09-12 00:11:48,959 - subp.py[DEBUG]: Running command ['blkid', '-tLABEL=CIDATA', '-odevice'] with allowed return codes [0, 2] (shell=False, capture=True)
2025-09-12 00:11:48,982 - subp.py[DEBUG]: Running command ['blkid', '-tLABEL=cidata', '-odevice'] with allowed return codes [0, 2] (shell=False, capture=True)
2025-09-12 00:11:49,005 - subp.py[DEBUG]: Running command ['blkid', '-tLABEL_FATBOOT=cidata', '-odevice'] with allowed return codes [0, 2] (shell=False, capture=True)
2025-09-12 00:11:49,028 - DataSourceNoCloud.py[DEBUG]: Seed from file:///boot/firmware not supported by DataSourceNoCloudNet [seed=None][dsmode=net]
2025-09-12 00:11:49,028 - __init__.py[DEBUG]: Datasource DataSourceNoCloudNet [seed=None][dsmode=net] not updated for events: boot-new-instance
2025-09-12 00:11:49,029 - handlers.py[DEBUG]: finish: init-network/search-NoCloudNet: SUCCESS: no network data found from DataSourceNoCloudNet
2025-09-12 00:11:49,029 - handlers.py[DEBUG]: start: init-network/search-None: searching for network data from DataSourceNone
2025-09-12 00:11:49,029 - __init__.py[DEBUG]: Seeing if we can get any data from <class 'cloudinit.sources.DataSourceNone.DataSourceNone'>
2025-09-12 00:11:49,030 - __init__.py[DEBUG]: Update datasource metadata and network config due to events: boot-new-instance
2025-09-12 00:11:49,030 - util.py[DEBUG]: Reading from /etc/hosts (quiet=False)
2025-09-12 00:11:49,031 - util.py[DEBUG]: Read 132 bytes from /etc/hosts
2025-09-12 00:11:49,034 - util.py[DEBUG]: Writing to /run/cloud-init/cloud-id-none - wb: [644] 5 bytes
2025-09-12 00:11:49,036 - util.py[DEBUG]: Creating symbolic link from '/run/cloud-init/cloud-id' => '/run/cloud-init/cloud-id-none'
2025-09-12 00:11:49,038 - atomic_helper.py[DEBUG]: Atomically writing to file /run/cloud-init/instance-data-sensitive.json (via temporary file /run/cloud-init/tmpfev7i7f0) - w: [600] 4864 bytes/chars
2025-09-12 00:11:49,040 - atomic_helper.py[DEBUG]: Atomically writing to file /run/cloud-init/instance-data.json (via temporary file /run/cloud-init/tmppiow6e35) - w: [644] 1367 bytes/chars
2025-09-12 00:11:49,040 - handlers.py[DEBUG]: finish: init-network/search-None: SUCCESS: found network data from DataSourceNone
2025-09-12 00:11:49,041 - stages.py[INFO]: Loaded datasource DataSourceNone - DataSourceNone
2025-09-12 00:11:49,041 - util.py[DEBUG]: Reading from /etc/cloud/cloud.cfg (quiet=False)
2025-09-12 00:11:49,042 - util.py[DEBUG]: Read 2796 bytes from /etc/cloud/cloud.cfg
2025-09-12 00:11:49,042 - util.py[DEBUG]: Attempting to load yaml from string of length 2796 with allowed root types (<class 'dict'>,)
2025-09-12 00:11:49,080 - util.py[DEBUG]: Reading from /etc/cloud/cloud.cfg.d/99_raspberry-pi.cfg (quiet=False)
2025-09-12 00:11:49,081 - util.py[DEBUG]: Read 755 bytes from /etc/cloud/cloud.cfg.d/99_raspberry-pi.cfg
2025-09-12 00:11:49,081 - util.py[DEBUG]: Attempting to load yaml from string of length 755 with allowed root types (<class 'dict'>,)
2025-09-12 00:11:49,089 - util.py[DEBUG]: Reading from /etc/cloud/cloud.cfg.d/05_logging.cfg (quiet=False)
2025-09-12 00:11:49,090 - util.py[DEBUG]: Read 2070 bytes from /etc/cloud/cloud.cfg.d/05_logging.cfg
2025-09-12 00:11:49,090 - util.py[DEBUG]: Attempting to load yaml from string of length 2070 with allowed root types (<class 'dict'>,)
2025-09-12 00:11:49,105 - util.py[DEBUG]: Reading from /run/cloud-init/cloud.cfg (quiet=False)
2025-09-12 00:11:49,105 - util.py[DEBUG]: Read 35 bytes from /run/cloud-init/cloud.cfg
2025-09-12 00:11:49,105 - util.py[DEBUG]: Attempting to load yaml from string of length 35 with allowed root types (<class 'dict'>,)
2025-09-12 00:11:49,107 - util.py[DEBUG]: Attempting to load yaml from string of length 0 with allowed root types (<class 'dict'>,)
2025-09-12 00:11:49,107 - util.py[DEBUG]: loaded blob returned None, returning default.
2025-09-12 00:11:49,109 - util.py[DEBUG]: Attempting to remove /var/lib/cloud/instance
2025-09-12 00:11:49,110 - util.py[DEBUG]: Creating symbolic link from '/var/lib/cloud/instance' => '/var/lib/cloud/instances/iid-datasource-none'
2025-09-12 00:11:49,116 - util.py[DEBUG]: Reading from /var/lib/cloud/instances/iid-datasource-none/datasource (quiet=False)
2025-09-12 00:11:49,116 - util.py[DEBUG]: Writing to /var/lib/cloud/instances/iid-datasource-none/datasource - wb: [644] 31 bytes
2025-09-12 00:11:49,122 - util.py[DEBUG]: Writing to /var/lib/cloud/data/previous-datasource - wb: [644] 31 bytes
2025-09-12 00:11:49,124 - util.py[DEBUG]: Reading from /var/lib/cloud/data/instance-id (quiet=False)
2025-09-12 00:11:49,124 - stages.py[DEBUG]: previous iid found to be NO_PREVIOUS_INSTANCE_ID
2025-09-12 00:11:49,124 - util.py[DEBUG]: Writing to /var/lib/cloud/data/instance-id - wb: [644] 20 bytes
2025-09-12 00:11:49,126 - util.py[DEBUG]: Writing to /run/cloud-init/.instance-id - wb: [644] 20 bytes
2025-09-12 00:11:49,127 - util.py[DEBUG]: Writing to /var/lib/cloud/data/previous-instance-id - wb: [644] 24 bytes
2025-09-12 00:11:49,130 - util.py[DEBUG]: Writing to /var/lib/cloud/instance/obj.pkl - wb: [400] 4262 bytes
2025-09-12 00:11:49,132 - main.py[DEBUG]: [net] init will now be targeting instance id: iid-datasource-none. new=True
2025-09-12 00:11:49,133 - util.py[DEBUG]: Reading from /etc/cloud/cloud.cfg (quiet=False)
2025-09-12 00:11:49,133 - util.py[DEBUG]: Read 2796 bytes from /etc/cloud/cloud.cfg
2025-09-12 00:11:49,133 - util.py[DEBUG]: Attempting to load yaml from string of length 2796 with allowed root types (<class 'dict'>,)
2025-09-12 00:11:49,171 - util.py[DEBUG]: Reading from /etc/cloud/cloud.cfg.d/99_raspberry-pi.cfg (quiet=False)
2025-09-12 00:11:49,171 - util.py[DEBUG]: Read 755 bytes from /etc/cloud/cloud.cfg.d/99_raspberry-pi.cfg
2025-09-12 00:11:49,172 - util.py[DEBUG]: Attempting to load yaml from string of length 755 with allowed root types (<class 'dict'>,)
2025-09-12 00:11:49,180 - util.py[DEBUG]: Reading from /etc/cloud/cloud.cfg.d/05_logging.cfg (quiet=False)
2025-09-12 00:11:49,180 - util.py[DEBUG]: Read 2070 bytes from /etc/cloud/cloud.cfg.d/05_logging.cfg
2025-09-12 00:11:49,181 - util.py[DEBUG]: Attempting to load yaml from string of length 2070 with allowed root types (<class 'dict'>,)
2025-09-12 00:11:49,195 - util.py[DEBUG]: Reading from /run/cloud-init/cloud.cfg (quiet=False)
2025-09-12 00:11:49,196 - util.py[DEBUG]: Read 35 bytes from /run/cloud-init/cloud.cfg
2025-09-12 00:11:49,196 - util.py[DEBUG]: Attempting to load yaml from string of length 35 with allowed root types (<class 'dict'>,)
2025-09-12 00:11:49,198 - util.py[DEBUG]: Attempting to load yaml from string of length 0 with allowed root types (<class 'dict'>,)
2025-09-12 00:11:49,198 - util.py[DEBUG]: loaded blob returned None, returning default.
2025-09-12 00:11:49,202 - util.py[DEBUG]: Reading from /sys/class/net/wlan0/address (quiet=False)
2025-09-12 00:11:49,202 - util.py[DEBUG]: Read 18 bytes from /sys/class/net/wlan0/address
2025-09-12 00:11:49,203 - util.py[DEBUG]: Reading from /sys/class/net/lo/address (quiet=False)
2025-09-12 00:11:49,203 - util.py[DEBUG]: Read 18 bytes from /sys/class/net/lo/address
2025-09-12 00:11:49,203 - util.py[DEBUG]: Reading from /sys/class/net/eth0/address (quiet=False)
2025-09-12 00:11:49,203 - util.py[DEBUG]: Read 18 bytes from /sys/class/net/eth0/address
2025-09-12 00:11:49,205 - stages.py[DEBUG]: Using distro class <class 'cloudinit.distros.debian.Distro'>
2025-09-12 00:11:49,206 - util.py[DEBUG]: Reading from /sys/class/net/wlan0/name_assign_type (quiet=False)
2025-09-12 00:11:49,207 - util.py[DEBUG]: Reading from /sys/class/net/eth0/name_assign_type (quiet=False)
2025-09-12 00:11:49,207 - util.py[DEBUG]: Read 2 bytes from /sys/class/net/eth0/name_assign_type
2025-09-12 00:11:49,207 - __init__.py[DEBUG]: Found unstable nic names: ['wlan0', 'eth0']; calling udevadm settle
2025-09-12 00:11:49,208 - subp.py[DEBUG]: Running command ['udevadm', 'settle'] with allowed return codes [0] (shell=False, capture=True)
2025-09-12 00:11:49,221 - util.py[DEBUG]: Waiting for udev events to settle took 0.013 seconds
2025-09-12 00:11:49,221 - util.py[DEBUG]: Reading from /sys/class/net/wlan0/address (quiet=False)
2025-09-12 00:11:49,222 - util.py[DEBUG]: Read 18 bytes from /sys/class/net/wlan0/address
2025-09-12 00:11:49,222 - util.py[DEBUG]: Reading from /sys/class/net/wlan0/carrier (quiet=False)
2025-09-12 00:11:49,222 - __init__.py[DEBUG]: Interface has no carrier: wlan0
2025-09-12 00:11:49,223 - util.py[DEBUG]: Reading from /sys/class/net/wlan0/dormant (quiet=False)
2025-09-12 00:11:49,223 - util.py[DEBUG]: Reading from /sys/class/net/wlan0/operstate (quiet=False)
2025-09-12 00:11:49,223 - util.py[DEBUG]: Read 5 bytes from /sys/class/net/wlan0/operstate
2025-09-12 00:11:49,223 - util.py[DEBUG]: Reading from /sys/class/net/eth0/address (quiet=False)
2025-09-12 00:11:49,224 - util.py[DEBUG]: Read 18 bytes from /sys/class/net/eth0/address
2025-09-12 00:11:49,224 - util.py[DEBUG]: Reading from /sys/class/net/eth0/carrier (quiet=False)
2025-09-12 00:11:49,224 - __init__.py[DEBUG]: Interface has no carrier: eth0
2025-09-12 00:11:49,224 - util.py[DEBUG]: Reading from /sys/class/net/eth0/dormant (quiet=False)
2025-09-12 00:11:49,225 - util.py[DEBUG]: Reading from /sys/class/net/eth0/operstate (quiet=False)
2025-09-12 00:11:49,225 - util.py[DEBUG]: Read 5 bytes from /sys/class/net/eth0/operstate
2025-09-12 00:11:49,225 - util.py[DEBUG]: Reading from /sys/class/net/eth0/address (quiet=False)
2025-09-12 00:11:49,226 - util.py[DEBUG]: Read 18 bytes from /sys/class/net/eth0/address
2025-09-12 00:11:49,227 - util.py[DEBUG]: Reading from /sys/class/net/wlan0/address (quiet=False)
2025-09-12 00:11:49,227 - util.py[DEBUG]: Read 18 bytes from /sys/class/net/wlan0/address
2025-09-12 00:11:49,227 - util.py[DEBUG]: Reading from /sys/class/net/lo/address (quiet=False)
2025-09-12 00:11:49,227 - util.py[DEBUG]: Read 18 bytes from /sys/class/net/lo/address
2025-09-12 00:11:49,227 - util.py[DEBUG]: Reading from /sys/class/net/eth0/address (quiet=False)
2025-09-12 00:11:49,228 - util.py[DEBUG]: Read 18 bytes from /sys/class/net/eth0/address
2025-09-12 00:11:49,229 - util.py[DEBUG]: Reading from /sys/class/net/wlan0/name_assign_type (quiet=False)
2025-09-12 00:11:49,229 - util.py[DEBUG]: Reading from /sys/class/net/eth0/name_assign_type (quiet=False)
2025-09-12 00:11:49,229 - util.py[DEBUG]: Read 2 bytes from /sys/class/net/eth0/name_assign_type
2025-09-12 00:11:49,229 - __init__.py[DEBUG]: Found unstable nic names: ['wlan0', 'eth0']; calling udevadm settle
2025-09-12 00:11:49,230 - subp.py[DEBUG]: Running command ['udevadm', 'settle'] with allowed return codes [0] (shell=False, capture=True)
2025-09-12 00:11:49,290 - util.py[DEBUG]: Waiting for udev events to settle took 0.061 seconds
2025-09-12 00:11:49,291 - util.py[DEBUG]: Reading from /sys/class/net/wlan0/address (quiet=False)
2025-09-12 00:11:49,291 - util.py[DEBUG]: Read 18 bytes from /sys/class/net/wlan0/address
2025-09-12 00:11:49,292 - util.py[DEBUG]: Reading from /sys/class/net/wlan0/carrier (quiet=False)
2025-09-12 00:11:49,292 - __init__.py[DEBUG]: Interface has no carrier: wlan0
2025-09-12 00:11:49,292 - util.py[DEBUG]: Reading from /sys/class/net/wlan0/dormant (quiet=False)
2025-09-12 00:11:49,292 - util.py[DEBUG]: Reading from /sys/class/net/wlan0/operstate (quiet=False)
2025-09-12 00:11:49,293 - util.py[DEBUG]: Read 5 bytes from /sys/class/net/wlan0/operstate
2025-09-12 00:11:49,293 - util.py[DEBUG]: Reading from /sys/class/net/eth0/address (quiet=False)
2025-09-12 00:11:49,293 - util.py[DEBUG]: Read 18 bytes from /sys/class/net/eth0/address
2025-09-12 00:11:49,294 - util.py[DEBUG]: Reading from /sys/class/net/eth0/carrier (quiet=False)
2025-09-12 00:11:49,294 - __init__.py[DEBUG]: Interface has no carrier: eth0
2025-09-12 00:11:49,294 - util.py[DEBUG]: Reading from /sys/class/net/eth0/dormant (quiet=False)
2025-09-12 00:11:49,294 - util.py[DEBUG]: Reading from /sys/class/net/eth0/operstate (quiet=False)
2025-09-12 00:11:49,295 - util.py[DEBUG]: Read 5 bytes from /sys/class/net/eth0/operstate
2025-09-12 00:11:49,295 - util.py[DEBUG]: Reading from /sys/class/net/eth0/address (quiet=False)
2025-09-12 00:11:49,295 - util.py[DEBUG]: Read 18 bytes from /sys/class/net/eth0/address
2025-09-12 00:11:49,296 - util.py[DEBUG]: Reading from /sys/class/net/eth0/device/device (quiet=False)
2025-09-12 00:11:49,296 - util.py[DEBUG]: Reading from /sys/class/net/wlan0/addr_assign_type (quiet=False)
2025-09-12 00:11:49,296 - util.py[DEBUG]: Read 2 bytes from /sys/class/net/wlan0/addr_assign_type
2025-09-12 00:11:49,296 - util.py[DEBUG]: Reading from /sys/class/net/wlan0/uevent (quiet=False)
2025-09-12 00:11:49,297 - util.py[DEBUG]: Read 39 bytes from /sys/class/net/wlan0/uevent
2025-09-12 00:11:49,297 - util.py[DEBUG]: Reading from /sys/class/net/wlan0/address (quiet=False)
2025-09-12 00:11:49,297 - util.py[DEBUG]: Read 18 bytes from /sys/class/net/wlan0/address
2025-09-12 00:11:49,298 - __init__.py[DEBUG]: ovs-vsctl not in PATH; not detecting Open vSwitch interfaces
2025-09-12 00:11:49,298 - util.py[DEBUG]: Reading from /sys/class/net/wlan0/device/device (quiet=False)
2025-09-12 00:11:49,298 - util.py[DEBUG]: Read 7 bytes from /sys/class/net/wlan0/device/device
2025-09-12 00:11:49,298 - util.py[DEBUG]: Reading from /sys/class/net/lo/addr_assign_type (quiet=False)
2025-09-12 00:11:49,299 - util.py[DEBUG]: Read 2 bytes from /sys/class/net/lo/addr_assign_type
2025-09-12 00:11:49,299 - util.py[DEBUG]: Reading from /sys/class/net/lo/uevent (quiet=False)
2025-09-12 00:11:49,299 - util.py[DEBUG]: Read 23 bytes from /sys/class/net/lo/uevent
2025-09-12 00:11:49,299 - util.py[DEBUG]: Reading from /sys/class/net/lo/address (quiet=False)
2025-09-12 00:11:49,300 - util.py[DEBUG]: Read 18 bytes from /sys/class/net/lo/address
2025-09-12 00:11:49,300 - util.py[DEBUG]: Reading from /sys/class/net/lo/device/device (quiet=False)
2025-09-12 00:11:49,300 - util.py[DEBUG]: Reading from /sys/class/net/eth0/addr_assign_type (quiet=False)
2025-09-12 00:11:49,301 - util.py[DEBUG]: Read 2 bytes from /sys/class/net/eth0/addr_assign_type
2025-09-12 00:11:49,301 - util.py[DEBUG]: Reading from /sys/class/net/eth0/uevent (quiet=False)
2025-09-12 00:11:49,301 - util.py[DEBUG]: Read 25 bytes from /sys/class/net/eth0/uevent
2025-09-12 00:11:49,301 - util.py[DEBUG]: Reading from /sys/class/net/eth0/address (quiet=False)
2025-09-12 00:11:49,302 - util.py[DEBUG]: Read 18 bytes from /sys/class/net/eth0/address
2025-09-12 00:11:49,302 - util.py[DEBUG]: Reading from /sys/class/net/eth0/device/device (quiet=False)
2025-09-12 00:11:49,302 - util.py[DEBUG]: Reading from /sys/class/net/wlan0/type (quiet=False)
2025-09-12 00:11:49,302 - util.py[DEBUG]: Read 2 bytes from /sys/class/net/wlan0/type
2025-09-12 00:11:49,303 - util.py[DEBUG]: Reading from /sys/class/net/lo/type (quiet=False)
2025-09-12 00:11:49,303 - util.py[DEBUG]: Read 4 bytes from /sys/class/net/lo/type
2025-09-12 00:11:49,303 - util.py[DEBUG]: Reading from /sys/class/net/eth0/type (quiet=False)
2025-09-12 00:11:49,303 - util.py[DEBUG]: Read 2 bytes from /sys/class/net/eth0/type
2025-09-12 00:11:49,303 - networking.py[DEBUG]: net: all expected physical devices present
2025-09-12 00:11:49,304 - stages.py[DEBUG]: applying net config names for {'ethernets': {'eth0': {'dhcp4': True, 'set-name': 'eth0', 'match': {'macaddress': 'b8:27:eb:65:09:fc'}}}, 'version': 2}
2025-09-12 00:11:49,304 - util.py[DEBUG]: Reading from /sys/class/net/eth0/device/device (quiet=False)
2025-09-12 00:11:49,304 - util.py[DEBUG]: Reading from /sys/class/net/wlan0/addr_assign_type (quiet=False)
2025-09-12 00:11:49,305 - util.py[DEBUG]: Read 2 bytes from /sys/class/net/wlan0/addr_assign_type
2025-09-12 00:11:49,305 - util.py[DEBUG]: Reading from /sys/class/net/wlan0/uevent (quiet=False)
2025-09-12 00:11:49,305 - util.py[DEBUG]: Read 39 bytes from /sys/class/net/wlan0/uevent
2025-09-12 00:11:49,305 - util.py[DEBUG]: Reading from /sys/class/net/wlan0/address (quiet=False)
2025-09-12 00:11:49,306 - util.py[DEBUG]: Read 18 bytes from /sys/class/net/wlan0/address
2025-09-12 00:11:49,306 - util.py[DEBUG]: Reading from /sys/class/net/wlan0/device/device (quiet=False)
2025-09-12 00:11:49,306 - util.py[DEBUG]: Read 7 bytes from /sys/class/net/wlan0/device/device
2025-09-12 00:11:49,306 - util.py[DEBUG]: Reading from /sys/class/net/lo/addr_assign_type (quiet=False)
2025-09-12 00:11:49,307 - util.py[DEBUG]: Read 2 bytes from /sys/class/net/lo/addr_assign_type
2025-09-12 00:11:49,307 - util.py[DEBUG]: Reading from /sys/class/net/lo/uevent (quiet=False)
2025-09-12 00:11:49,307 - util.py[DEBUG]: Read 23 bytes from /sys/class/net/lo/uevent
2025-09-12 00:11:49,307 - util.py[DEBUG]: Reading from /sys/class/net/lo/address (quiet=False)
2025-09-12 00:11:49,308 - util.py[DEBUG]: Read 18 bytes from /sys/class/net/lo/address
2025-09-12 00:11:49,308 - util.py[DEBUG]: Reading from /sys/class/net/lo/device/device (quiet=False)
2025-09-12 00:11:49,308 - util.py[DEBUG]: Reading from /sys/class/net/eth0/addr_assign_type (quiet=False)
2025-09-12 00:11:49,308 - util.py[DEBUG]: Read 2 bytes from /sys/class/net/eth0/addr_assign_type
2025-09-12 00:11:49,308 - util.py[DEBUG]: Reading from /sys/class/net/eth0/uevent (quiet=False)
2025-09-12 00:11:49,309 - util.py[DEBUG]: Read 25 bytes from /sys/class/net/eth0/uevent
2025-09-12 00:11:49,309 - util.py[DEBUG]: Reading from /sys/class/net/eth0/address (quiet=False)
2025-09-12 00:11:49,309 - util.py[DEBUG]: Read 18 bytes from /sys/class/net/eth0/address
2025-09-12 00:11:49,310 - util.py[DEBUG]: Reading from /sys/class/net/eth0/device/device (quiet=False)
2025-09-12 00:11:49,310 - util.py[DEBUG]: Reading from /sys/class/net/wlan0/operstate (quiet=False)
2025-09-12 00:11:49,310 - util.py[DEBUG]: Read 5 bytes from /sys/class/net/wlan0/operstate
2025-09-12 00:11:49,310 - util.py[DEBUG]: Reading from /sys/class/net/lo/operstate (quiet=False)
2025-09-12 00:11:49,311 - util.py[DEBUG]: Read 8 bytes from /sys/class/net/lo/operstate
2025-09-12 00:11:49,311 - util.py[DEBUG]: Reading from /sys/class/net/eth0/operstate (quiet=False)
2025-09-12 00:11:49,311 - util.py[DEBUG]: Read 5 bytes from /sys/class/net/eth0/operstate
2025-09-12 00:11:49,312 - subp.py[DEBUG]: Running command ['ip', '-6', 'addr', 'show', 'permanent', 'scope', 'global'] with allowed return codes [0] (shell=False, capture=True)
2025-09-12 00:11:49,317 - subp.py[DEBUG]: Running command ['ip', '-4', 'addr', 'show'] with allowed return codes [0] (shell=False, capture=True)
2025-09-12 00:11:49,323 - __init__.py[DEBUG]: Detected interfaces {'wlan0': {'downable': True, 'device_id': '0xa9a6', 'driver': 'brcmfmac', 'mac': 'b8:27:eb:30:5c:a9', 'name': 'wlan0', 'up': False}, 'lo': {'downable': False, 'device_id': None, 'driver': None, 'mac': '00:00:00:00:00:00', 'name': 'lo', 'up': True}, 'eth0': {'downable': True, 'device_id': None, 'driver': 'lan78xx', 'mac': 'b8:27:eb:65:09:fc', 'name': 'eth0', 'up': False}}
2025-09-12 00:11:49,323 - __init__.py[DEBUG]: no work necessary for renaming of [['b8:27:eb:65:09:fc', 'eth0', 'lan78xx', None]]
2025-09-12 00:11:49,324 - stages.py[INFO]: Applying network configuration from fallback bringup=True: {'ethernets': {'eth0': {'dhcp4': True, 'set-name': 'eth0', 'match': {'macaddress': 'b8:27:eb:65:09:fc'}}}, 'version': 2}
2025-09-12 00:11:49,325 - subp.py[DEBUG]: Running command ['systemctl', 'is-enabled', 'NetworkManager.service'] with allowed return codes [0] (shell=False, capture=True)
2025-09-12 00:11:49,355 - __init__.py[DEBUG]: Selected renderer 'network-manager' from priority list: None
2025-09-12 00:11:49,355 - util.py[DEBUG]: Reading from /sys/class/net/wlan0/addr_assign_type (quiet=False)
2025-09-12 00:11:49,356 - util.py[DEBUG]: Read 2 bytes from /sys/class/net/wlan0/addr_assign_type
2025-09-12 00:11:49,356 - util.py[DEBUG]: Reading from /sys/class/net/wlan0/uevent (quiet=False)
2025-09-12 00:11:49,356 - util.py[DEBUG]: Read 39 bytes from /sys/class/net/wlan0/uevent
2025-09-12 00:11:49,357 - util.py[DEBUG]: Reading from /sys/class/net/wlan0/address (quiet=False)
2025-09-12 00:11:49,357 - util.py[DEBUG]: Read 18 bytes from /sys/class/net/wlan0/address
2025-09-12 00:11:49,357 - util.py[DEBUG]: Reading from /sys/class/net/wlan0/device/device (quiet=False)
2025-09-12 00:11:49,357 - util.py[DEBUG]: Read 7 bytes from /sys/class/net/wlan0/device/device
2025-09-12 00:11:49,358 - util.py[DEBUG]: Reading from /sys/class/net/lo/addr_assign_type (quiet=False)
2025-09-12 00:11:49,358 - util.py[DEBUG]: Read 2 bytes from /sys/class/net/lo/addr_assign_type
2025-09-12 00:11:49,358 - util.py[DEBUG]: Reading from /sys/class/net/lo/uevent (quiet=False)
2025-09-12 00:11:49,358 - util.py[DEBUG]: Read 23 bytes from /sys/class/net/lo/uevent
2025-09-12 00:11:49,359 - util.py[DEBUG]: Reading from /sys/class/net/lo/address (quiet=False)
2025-09-12 00:11:49,359 - util.py[DEBUG]: Read 18 bytes from /sys/class/net/lo/address
2025-09-12 00:11:49,359 - util.py[DEBUG]: Reading from /sys/class/net/lo/device/device (quiet=False)
2025-09-12 00:11:49,359 - util.py[DEBUG]: Reading from /sys/class/net/eth0/addr_assign_type (quiet=False)
2025-09-12 00:11:49,359 - util.py[DEBUG]: Read 2 bytes from /sys/class/net/eth0/addr_assign_type
2025-09-12 00:11:49,360 - util.py[DEBUG]: Reading from /sys/class/net/eth0/uevent (quiet=False)
2025-09-12 00:11:49,360 - util.py[DEBUG]: Read 25 bytes from /sys/class/net/eth0/uevent
2025-09-12 00:11:49,361 - util.py[DEBUG]: Reading from /sys/class/net/eth0/address (quiet=False)
2025-09-12 00:11:49,361 - util.py[DEBUG]: Read 18 bytes from /sys/class/net/eth0/address
2025-09-12 00:11:49,361 - util.py[DEBUG]: Reading from /sys/class/net/eth0/device/device (quiet=False)
2025-09-12 00:11:49,361 - util.py[DEBUG]: Reading from /sys/class/net/wlan0/type (quiet=False)
2025-09-12 00:11:49,362 - util.py[DEBUG]: Read 2 bytes from /sys/class/net/wlan0/type
2025-09-12 00:11:49,362 - util.py[DEBUG]: Reading from /sys/class/net/lo/type (quiet=False)
2025-09-12 00:11:49,362 - util.py[DEBUG]: Read 4 bytes from /sys/class/net/lo/type
2025-09-12 00:11:49,362 - util.py[DEBUG]: Reading from /sys/class/net/eth0/type (quiet=False)
2025-09-12 00:11:49,362 - util.py[DEBUG]: Read 2 bytes from /sys/class/net/eth0/type
2025-09-12 00:11:49,363 - network_state.py[DEBUG]: v2(ethernets) -> v1(physical):
{'type': 'physical', 'mac_address': 'b8:27:eb:65:09:fc', 'name': 'eth0', 'match': {'macaddress': 'b8:27:eb:65:09:fc'}, 'subnets': [{'type': 'dhcp4'}]}
2025-09-12 00:11:49,371 - network_state.py[DEBUG]: v2_common: handling config:
{'eth0': {'dhcp4': True, 'set-name': 'eth0', 'match': {'macaddress': 'b8:27:eb:65:09:fc'}}}
2025-09-12 00:11:49,374 - util.py[DEBUG]: Writing to /etc/NetworkManager/system-connections/cloud-init-eth0.nmconnection - wb: [600] 273 bytes
2025-09-12 00:11:49,376 - __init__.py[DEBUG]: Bringing up newly configured network interfaces
2025-09-12 00:11:49,376 - subp.py[DEBUG]: Running command ['systemctl', 'is-enabled', 'NetworkManager.service'] with allowed return codes [0] (shell=False, capture=True)
2025-09-12 00:11:49,406 - activators.py[DEBUG]: Using selected activator: <class 'cloudinit.net.activators.NetworkManagerActivator'> from priority: ['eni', 'netplan', 'network-manager', 'networkd']
2025-09-12 00:11:49,407 - activators.py[DEBUG]: Attempting command ['nmcli', 'connection', 'load', '/etc/NetworkManager/system-connections/cloud-init-eth0.nmconnection'] for device eth0
2025-09-12 00:11:49,407 - subp.py[DEBUG]: Running command ['nmcli', 'connection', 'load', '/etc/NetworkManager/system-connections/cloud-init-eth0.nmconnection'] with allowed return codes [0] (shell=False, capture=True)
2025-09-12 00:11:49,775 - util.py[WARNING]: Running interface command ['nmcli', 'connection', 'load', '/etc/NetworkManager/system-connections/cloud-init-eth0.nmconnection'] failed
2025-09-12 00:11:49,775 - util.py[DEBUG]: Running interface command ['nmcli', 'connection', 'load', '/etc/NetworkManager/system-connections/cloud-init-eth0.nmconnection'] failed
Traceback (most recent call last):
  File "/usr/lib/python3/dist-packages/cloudinit/net/activators.py", line 23, in _alter_interface
    (_out, err) = subp.subp(cmd)
                  ^^^^^^^^^^^^^^
  File "/usr/lib/python3/dist-packages/cloudinit/subp.py", line 335, in subp
    raise ProcessExecutionError(
cloudinit.subp.ProcessExecutionError: Unexpected error while running command.
Command: ['nmcli', 'connection', 'load', '/etc/NetworkManager/system-connections/cloud-init-eth0.nmconnection']
Exit code: 1
Reason: -
Stdout:
Stderr: Error: Could not create NMClient object: Could not connect: No such file or directory.
2025-09-12 00:11:49,781 - activators.py[DEBUG]: Attempting command ['nmcli', 'connection', 'reload'] for device eth0
2025-09-12 00:11:49,781 - subp.py[DEBUG]: Running command ['nmcli', 'connection', 'reload'] with allowed return codes [0] (shell=False, capture=True)
2025-09-12 00:11:49,808 - util.py[WARNING]: Running interface command ['nmcli', 'connection', 'reload'] failed
2025-09-12 00:11:49,808 - util.py[DEBUG]: Running interface command ['nmcli', 'connection', 'reload'] failed
Traceback (most recent call last):
  File "/usr/lib/python3/dist-packages/cloudinit/net/activators.py", line 23, in _alter_interface
    (_out, err) = subp.subp(cmd)
                  ^^^^^^^^^^^^^^
  File "/usr/lib/python3/dist-packages/cloudinit/subp.py", line 335, in subp
    raise ProcessExecutionError(
cloudinit.subp.ProcessExecutionError: Unexpected error while running command.
Command: ['nmcli', 'connection', 'reload']
Exit code: 1
Reason: -
Stdout:
Stderr: Error: failed to reload connections: Could not connect: No such file or directory.
2025-09-12 00:11:49,810 - activators.py[DEBUG]: Attempting command ['nmcli', 'connection', 'up', 'ifname', 'eth0'] for device eth0
2025-09-12 00:11:49,810 - subp.py[DEBUG]: Running command ['nmcli', 'connection', 'up', 'ifname', 'eth0'] with allowed return codes [0] (shell=False, capture=True)
2025-09-12 00:11:49,838 - util.py[WARNING]: Running interface command ['nmcli', 'connection', 'up', 'ifname', 'eth0'] failed
2025-09-12 00:11:49,838 - util.py[DEBUG]: Running interface command ['nmcli', 'connection', 'up', 'ifname', 'eth0'] failed
Traceback (most recent call last):
  File "/usr/lib/python3/dist-packages/cloudinit/net/activators.py", line 23, in _alter_interface
    (_out, err) = subp.subp(cmd)
                  ^^^^^^^^^^^^^^
  File "/usr/lib/python3/dist-packages/cloudinit/subp.py", line 335, in subp
    raise ProcessExecutionError(
cloudinit.subp.ProcessExecutionError: Unexpected error while running command.
Command: ['nmcli', 'connection', 'up', 'ifname', 'eth0']
Exit code: 1
Reason: -
Stdout:
Stderr: Error: Could not create NMClient object: Could not connect: No such file or directory.
2025-09-12 00:11:49,840 - handlers.py[DEBUG]: start: init-network/setup-datasource: setting up datasource
2025-09-12 00:11:49,841 - handlers.py[DEBUG]: finish: init-network/setup-datasource: SUCCESS: setting up datasource
2025-09-12 00:11:49,841 - util.py[DEBUG]: Writing to /var/lib/cloud/instances/iid-datasource-none/user-data.txt - wb: [600] 0 bytes
2025-09-12 00:11:49,852 - util.py[DEBUG]: Writing to /var/lib/cloud/instances/iid-datasource-none/user-data.txt.i - wb: [600] 281 bytes
2025-09-12 00:11:49,854 - util.py[DEBUG]: Writing to /var/lib/cloud/instances/iid-datasource-none/vendor-data.txt - wb: [600] 0 bytes
2025-09-12 00:11:49,858 - util.py[DEBUG]: Writing to /var/lib/cloud/instances/iid-datasource-none/vendor-data.txt.i - wb: [600] 281 bytes
2025-09-12 00:11:49,860 - util.py[DEBUG]: Writing to /var/lib/cloud/instances/iid-datasource-none/vendor-data2.txt - wb: [600] 0 bytes
2025-09-12 00:11:49,864 - util.py[DEBUG]: Writing to /var/lib/cloud/instances/iid-datasource-none/vendor-data2.txt.i - wb: [600] 281 bytes
2025-09-12 00:11:49,868 - util.py[DEBUG]: Writing to /var/lib/cloud/instances/iid-datasource-none/sem/consume_data - wb: [644] 24 bytes
2025-09-12 00:11:49,870 - helpers.py[DEBUG]: Running consume_data using lock (<FileLock using file '/var/lib/cloud/instances/iid-datasource-none/sem/consume_data'>)
2025-09-12 00:11:49,870 - handlers.py[DEBUG]: start: init-network/consume-user-data: reading and applying user-data
2025-09-12 00:11:49,872 - stages.py[DEBUG]: Added default handler for {'text/cloud-config', 'text/cloud-config-jsonp'} from CloudConfigPartHandler: [['text/cloud-config', 'text/cloud-config-jsonp']]
2025-09-12 00:11:49,872 - stages.py[DEBUG]: Added default handler for {'text/x-shellscript'} from ShellScriptPartHandler: [['text/x-shellscript']]
2025-09-12 00:11:49,873 - stages.py[DEBUG]: Added default handler for {'text/x-shellscript-per-boot'} from ShellScriptByFreqPartHandler: [['text/x-shellscript-per-boot']]
2025-09-12 00:11:49,873 - stages.py[DEBUG]: Added default handler for {'text/x-shellscript-per-instance'} from ShellScriptByFreqPartHandler: [['text/x-shellscript-per-instance']]
2025-09-12 00:11:49,873 - stages.py[DEBUG]: Added default handler for {'text/x-shellscript-per-once'} from ShellScriptByFreqPartHandler: [['text/x-shellscript-per-once']]
2025-09-12 00:11:49,873 - stages.py[DEBUG]: Added default handler for {'text/cloud-boothook'} from BootHookPartHandler: [['text/cloud-boothook']]
2025-09-12 00:11:49,873 - stages.py[DEBUG]: Added default handler for {'text/jinja2'} from JinjaTemplatePartHandler: [['text/jinja2']]
2025-09-12 00:11:49,874 - __init__.py[DEBUG]: Calling handler CloudConfigPartHandler: [['text/cloud-config', 'text/cloud-config-jsonp']] (__begin__, None, 3) with frequency once-per-instance
2025-09-12 00:11:49,874 - __init__.py[DEBUG]: Calling handler ShellScriptPartHandler: [['text/x-shellscript']] (__begin__, None, 2) with frequency once-per-instance
2025-09-12 00:11:49,874 - __init__.py[DEBUG]: Calling handler ShellScriptByFreqPartHandler: [['text/x-shellscript-per-boot']] (__begin__, None, 2) with frequency once-per-instance
2025-09-12 00:11:49,875 - __init__.py[DEBUG]: Calling handler ShellScriptByFreqPartHandler: [['text/x-shellscript-per-instance']] (__begin__, None, 2) with frequency once-per-instance
2025-09-12 00:11:49,875 - __init__.py[DEBUG]: Calling handler ShellScriptByFreqPartHandler: [['text/x-shellscript-per-once']] (__begin__, None, 2) with frequency once-per-instance
2025-09-12 00:11:49,875 - __init__.py[DEBUG]: Calling handler BootHookPartHandler: [['text/cloud-boothook']] (__begin__, None, 2) with frequency once-per-instance
2025-09-12 00:11:49,875 - __init__.py[DEBUG]: Calling handler JinjaTemplatePartHandler: [['text/jinja2']] (__begin__, None, 3) with frequency once-per-instance
2025-09-12 00:11:49,875 - __init__.py[DEBUG]: {'MIME-Version': '1.0', 'Content-Type': 'text/x-not-multipart', 'Content-Disposition': 'attachment; filename="part-001"'}
2025-09-12 00:11:49,876 - __init__.py[DEBUG]: Empty payload of type text/x-not-multipart
2025-09-12 00:11:49,876 - __init__.py[DEBUG]: Calling handler CloudConfigPartHandler: [['text/cloud-config', 'text/cloud-config-jsonp']] (__end__, None, 3) with frequency once-per-instance
2025-09-12 00:11:49,876 - util.py[DEBUG]: Writing to /var/lib/cloud/instances/iid-datasource-none/cloud-config.txt - wb: [600] 0 bytes
2025-09-12 00:11:49,879 - __init__.py[DEBUG]: Calling handler ShellScriptPartHandler: [['text/x-shellscript']] (__end__, None, 2) with frequency once-per-instance
2025-09-12 00:11:49,879 - __init__.py[DEBUG]: Calling handler ShellScriptByFreqPartHandler: [['text/x-shellscript-per-boot']] (__end__, None, 2) with frequency once-per-instance
2025-09-12 00:11:49,879 - __init__.py[DEBUG]: Calling handler ShellScriptByFreqPartHandler: [['text/x-shellscript-per-instance']] (__end__, None, 2) with frequency once-per-instance
2025-09-12 00:11:49,880 - __init__.py[DEBUG]: Calling handler ShellScriptByFreqPartHandler: [['text/x-shellscript-per-once']] (__end__, None, 2) with frequency once-per-instance
2025-09-12 00:11:49,880 - __init__.py[DEBUG]: Calling handler BootHookPartHandler: [['text/cloud-boothook']] (__end__, None, 2) with frequency once-per-instance
2025-09-12 00:11:49,880 - __init__.py[DEBUG]: Calling handler JinjaTemplatePartHandler: [['text/jinja2']] (__end__, None, 3) with frequency once-per-instance
2025-09-12 00:11:49,880 - handlers.py[DEBUG]: finish: init-network/consume-user-data: SUCCESS: reading and applying user-data
2025-09-12 00:11:49,881 - handlers.py[DEBUG]: start: init-network/consume-vendor-data: reading and applying vendor-data
2025-09-12 00:11:49,881 - stages.py[DEBUG]: no vendordata from datasource
2025-09-12 00:11:49,881 - handlers.py[DEBUG]: finish: init-network/consume-vendor-data: SUCCESS: reading and applying vendor-data
2025-09-12 00:11:49,881 - handlers.py[DEBUG]: start: init-network/consume-vendor-data2: reading and applying vendor-data2
2025-09-12 00:11:49,882 - stages.py[DEBUG]: no vendordata2 from datasource
2025-09-12 00:11:49,882 - handlers.py[DEBUG]: finish: init-network/consume-vendor-data2: SUCCESS: reading and applying vendor-data2
2025-09-12 00:11:49,882 - util.py[DEBUG]: Reading from /etc/cloud/cloud.cfg (quiet=False)
2025-09-12 00:11:49,883 - util.py[DEBUG]: Read 2796 bytes from /etc/cloud/cloud.cfg
2025-09-12 00:11:49,883 - util.py[DEBUG]: Attempting to load yaml from string of length 2796 with allowed root types (<class 'dict'>,)
2025-09-12 00:11:49,921 - util.py[DEBUG]: Reading from /etc/cloud/cloud.cfg.d/99_raspberry-pi.cfg (quiet=False)
2025-09-12 00:11:49,921 - util.py[DEBUG]: Read 755 bytes from /etc/cloud/cloud.cfg.d/99_raspberry-pi.cfg
2025-09-12 00:11:49,922 - util.py[DEBUG]: Attempting to load yaml from string of length 755 with allowed root types (<class 'dict'>,)
2025-09-12 00:11:49,930 - util.py[DEBUG]: Reading from /etc/cloud/cloud.cfg.d/05_logging.cfg (quiet=False)
2025-09-12 00:11:49,930 - util.py[DEBUG]: Read 2070 bytes from /etc/cloud/cloud.cfg.d/05_logging.cfg
2025-09-12 00:11:49,931 - util.py[DEBUG]: Attempting to load yaml from string of length 2070 with allowed root types (<class 'dict'>,)
2025-09-12 00:11:49,945 - util.py[DEBUG]: Reading from /run/cloud-init/cloud.cfg (quiet=False)
2025-09-12 00:11:49,946 - util.py[DEBUG]: Read 35 bytes from /run/cloud-init/cloud.cfg
2025-09-12 00:11:49,946 - util.py[DEBUG]: Attempting to load yaml from string of length 35 with allowed root types (<class 'dict'>,)
2025-09-12 00:11:49,948 - util.py[DEBUG]: Attempting to load yaml from string of length 0 with allowed root types (<class 'dict'>,)
2025-09-12 00:11:49,948 - util.py[DEBUG]: loaded blob returned None, returning default.
2025-09-12 00:11:49,949 - util.py[DEBUG]: Reading from /var/lib/cloud/instance/cloud-config.txt (quiet=False)
2025-09-12 00:11:49,949 - util.py[DEBUG]: Read 0 bytes from /var/lib/cloud/instance/cloud-config.txt
2025-09-12 00:11:49,949 - util.py[DEBUG]: Attempting to load yaml from string of length 0 with allowed root types (<class 'dict'>,)
2025-09-12 00:11:49,950 - util.py[DEBUG]: loaded blob returned None, returning default.
2025-09-12 00:11:49,952 - util.py[DEBUG]: Reading from /usr/lib/python3/dist-packages/cloudinit/config/schemas/schema-cloud-config-v1.json (quiet=False)
2025-09-12 00:11:49,953 - util.py[DEBUG]: Read 133834 bytes from /usr/lib/python3/dist-packages/cloudinit/config/schemas/schema-cloud-config-v1.json
2025-09-12 00:11:49,995 - schema.py[WARNING]: Invalid cloud-config provided: Please run 'sudo cloud-init schema --system' to see the schema errors.
2025-09-12 00:11:49,997 - util.py[DEBUG]: Reading from /var/lib/cloud/instance/cloud-config.txt (quiet=False)
2025-09-12 00:11:49,997 - util.py[DEBUG]: Read 0 bytes from /var/lib/cloud/instance/cloud-config.txt
2025-09-12 00:11:49,998 - util.py[DEBUG]: Attempting to load yaml from string of length 0 with allowed root types (<class 'dict'>,)
2025-09-12 00:11:49,998 - util.py[DEBUG]: loaded blob returned None, returning default.
2025-09-12 00:11:50,007 - handlers.py[DEBUG]: start: init-network/activate-datasource: activating datasource
2025-09-12 00:11:50,010 - util.py[DEBUG]: Writing to /var/lib/cloud/instance/obj.pkl - wb: [400] 5806 bytes
2025-09-12 00:11:50,012 - handlers.py[DEBUG]: finish: init-network/activate-datasource: SUCCESS: activating datasource
2025-09-12 00:11:50,013 - main.py[DEBUG]: no di_report found in config.
2025-09-12 00:11:50,017 - util.py[DEBUG]: Reading from /usr/lib/python3/dist-packages/cloudinit/config/schemas/schema-cloud-config-v1.json (quiet=False)
2025-09-12 00:11:50,018 - util.py[DEBUG]: Read 133834 bytes from /usr/lib/python3/dist-packages/cloudinit/config/schemas/schema-cloud-config-v1.json
2025-09-12 00:11:50,033 - util.py[DEBUG]: Reading from /usr/lib/python3/dist-packages/cloudinit/config/schemas/schema-cloud-config-v1.json (quiet=False)
2025-09-12 00:11:50,034 - util.py[DEBUG]: Read 133834 bytes from /usr/lib/python3/dist-packages/cloudinit/config/schemas/schema-cloud-config-v1.json
2025-09-12 00:11:50,045 - util.py[DEBUG]: Reading from /usr/lib/python3/dist-packages/cloudinit/config/schemas/schema-cloud-config-v1.json (quiet=False)
2025-09-12 00:11:50,047 - util.py[DEBUG]: Read 133834 bytes from /usr/lib/python3/dist-packages/cloudinit/config/schemas/schema-cloud-config-v1.json
2025-09-12 00:11:50,058 - util.py[DEBUG]: Reading from /usr/lib/python3/dist-packages/cloudinit/config/schemas/schema-cloud-config-v1.json (quiet=False)
2025-09-12 00:11:50,059 - util.py[DEBUG]: Read 133834 bytes from /usr/lib/python3/dist-packages/cloudinit/config/schemas/schema-cloud-config-v1.json
2025-09-12 00:11:50,072 - util.py[DEBUG]: Reading from /usr/lib/python3/dist-packages/cloudinit/config/schemas/schema-cloud-config-v1.json (quiet=False)
2025-09-12 00:11:50,073 - util.py[DEBUG]: Read 133834 bytes from /usr/lib/python3/dist-packages/cloudinit/config/schemas/schema-cloud-config-v1.json
2025-09-12 00:11:50,085 - util.py[DEBUG]: Reading from /usr/lib/python3/dist-packages/cloudinit/config/schemas/schema-cloud-config-v1.json (quiet=False)
2025-09-12 00:11:50,086 - util.py[DEBUG]: Read 133834 bytes from /usr/lib/python3/dist-packages/cloudinit/config/schemas/schema-cloud-config-v1.json
2025-09-12 00:11:50,100 - util.py[DEBUG]: Reading from /usr/lib/python3/dist-packages/cloudinit/config/schemas/schema-cloud-config-v1.json (quiet=False)
2025-09-12 00:11:50,101 - util.py[DEBUG]: Read 133834 bytes from /usr/lib/python3/dist-packages/cloudinit/config/schemas/schema-cloud-config-v1.json
2025-09-12 00:11:50,115 - util.py[DEBUG]: Reading from /usr/lib/python3/dist-packages/cloudinit/config/schemas/schema-cloud-config-v1.json (quiet=False)
2025-09-12 00:11:50,116 - util.py[DEBUG]: Read 133834 bytes from /usr/lib/python3/dist-packages/cloudinit/config/schemas/schema-cloud-config-v1.json
2025-09-12 00:11:50,129 - util.py[DEBUG]: Reading from /usr/lib/python3/dist-packages/cloudinit/config/schemas/schema-cloud-config-v1.json (quiet=False)
2025-09-12 00:11:50,130 - util.py[DEBUG]: Read 133834 bytes from /usr/lib/python3/dist-packages/cloudinit/config/schemas/schema-cloud-config-v1.json
2025-09-12 00:11:50,141 - util.py[DEBUG]: Reading from /usr/lib/python3/dist-packages/cloudinit/config/schemas/schema-cloud-config-v1.json (quiet=False)
2025-09-12 00:11:50,142 - util.py[DEBUG]: Read 133834 bytes from /usr/lib/python3/dist-packages/cloudinit/config/schemas/schema-cloud-config-v1.json
2025-09-12 00:11:50,152 - util.py[DEBUG]: Reading from /usr/lib/python3/dist-packages/cloudinit/config/schemas/schema-cloud-config-v1.json (quiet=False)
2025-09-12 00:11:50,154 - util.py[DEBUG]: Read 133834 bytes from /usr/lib/python3/dist-packages/cloudinit/config/schemas/schema-cloud-config-v1.json
2025-09-12 00:11:50,165 - util.py[DEBUG]: Reading from /usr/lib/python3/dist-packages/cloudinit/config/schemas/schema-cloud-config-v1.json (quiet=False)
2025-09-12 00:11:50,166 - util.py[DEBUG]: Read 133834 bytes from /usr/lib/python3/dist-packages/cloudinit/config/schemas/schema-cloud-config-v1.json
2025-09-12 00:11:50,182 - util.py[DEBUG]: Reading from /usr/lib/python3/dist-packages/cloudinit/config/schemas/schema-cloud-config-v1.json (quiet=False)
2025-09-12 00:11:50,183 - util.py[DEBUG]: Read 133834 bytes from /usr/lib/python3/dist-packages/cloudinit/config/schemas/schema-cloud-config-v1.json
2025-09-12 00:11:50,199 - util.py[DEBUG]: Reading from /usr/lib/python3/dist-packages/cloudinit/config/schemas/schema-cloud-config-v1.json (quiet=False)
2025-09-12 00:11:50,200 - util.py[DEBUG]: Read 133834 bytes from /usr/lib/python3/dist-packages/cloudinit/config/schemas/schema-cloud-config-v1.json
2025-09-12 00:11:50,209 - stages.py[DEBUG]: Using distro class <class 'cloudinit.distros.debian.Distro'>
2025-09-12 00:11:50,217 - modules.py[INFO]: Skipping modules 'bootcmd,write-files,disk_setup,update_etc_hosts,ca-certs,rsyslog' because no applicable config is provided.
2025-09-12 00:11:50,218 - modules.py[DEBUG]: Running module migrator (<module 'cloudinit.config.cc_migrator' from '/usr/lib/python3/dist-packages/cloudinit/config/cc_migrator.py'>) with frequency always
2025-09-12 00:11:50,219 - handlers.py[DEBUG]: start: init-network/config-migrator: running config-migrator with frequency always
2025-09-12 00:11:50,219 - helpers.py[DEBUG]: Running config-migrator using lock (<cloudinit.helpers.DummyLock object at 0x7538beb0>)
2025-09-12 00:11:50,220 - cc_migrator.py[DEBUG]: Migrated 0 semaphore files to there canonicalized names
2025-09-12 00:11:50,221 - handlers.py[DEBUG]: finish: init-network/config-migrator: SUCCESS: config-migrator ran successfully
2025-09-12 00:11:50,221 - modules.py[DEBUG]: Running module seed_random (<module 'cloudinit.config.cc_seed_random' from '/usr/lib/python3/dist-packages/cloudinit/config/cc_seed_random.py'>) with frequency once-per-instance
2025-09-12 00:11:50,222 - handlers.py[DEBUG]: start: init-network/config-seed_random: running config-seed_random with frequency once-per-instance
2025-09-12 00:11:50,222 - util.py[DEBUG]: Writing to /var/lib/cloud/instances/iid-datasource-none/sem/config_seed_random - wb: [644] 24 bytes
2025-09-12 00:11:50,224 - helpers.py[DEBUG]: Running config-seed_random using lock (<FileLock using file '/var/lib/cloud/instances/iid-datasource-none/sem/config_seed_random'>)
2025-09-12 00:11:50,224 - cc_seed_random.py[DEBUG]: no command provided
2025-09-12 00:11:50,225 - handlers.py[DEBUG]: finish: init-network/config-seed_random: SUCCESS: config-seed_random ran successfully
2025-09-12 00:11:50,225 - modules.py[DEBUG]: Running module growpart (<module 'cloudinit.config.cc_growpart' from '/usr/lib/python3/dist-packages/cloudinit/config/cc_growpart.py'>) with frequency always
2025-09-12 00:11:50,225 - handlers.py[DEBUG]: start: init-network/config-growpart: running config-growpart with frequency always
2025-09-12 00:11:50,226 - helpers.py[DEBUG]: Running config-growpart using lock (<cloudinit.helpers.DummyLock object at 0x75399910>)
2025-09-12 00:11:50,226 - cc_growpart.py[DEBUG]: No 'growpart' entry in cfg.  Using default: {'mode': 'auto', 'devices': ['/'], 'ignore_growroot_disabled': False}
2025-09-12 00:11:50,226 - subp.py[DEBUG]: Running command ['growpart', '--help'] with allowed return codes [0] (shell=False, capture=True)
2025-09-12 00:11:50,242 - util.py[DEBUG]: Reading from /proc/422/mountinfo (quiet=False)
2025-09-12 00:11:50,243 - util.py[DEBUG]: Read 2561 bytes from /proc/422/mountinfo
2025-09-12 00:11:50,243 - util.py[DEBUG]: Reading from /sys/class/block/mmcblk0p2/partition (quiet=False)
2025-09-12 00:11:50,244 - util.py[DEBUG]: Read 2 bytes from /sys/class/block/mmcblk0p2/partition
2025-09-12 00:11:50,244 - util.py[DEBUG]: Reading from /sys/devices/platform/soc/3f202000.mmc/mmc_host/mmc0/mmc0:aaaa/block/mmcblk0/dev (quiet=False)
2025-09-12 00:11:50,245 - util.py[DEBUG]: Read 6 bytes from /sys/devices/platform/soc/3f202000.mmc/mmc_host/mmc0/mmc0:aaaa/block/mmcblk0/dev
2025-09-12 00:11:50,245 - util.py[DEBUG]: Reading from /proc/422/mountinfo (quiet=False)
2025-09-12 00:11:50,245 - util.py[DEBUG]: Read 2561 bytes from /proc/422/mountinfo
2025-09-12 00:11:50,246 - util.py[DEBUG]: Reading from /proc/422/mountinfo (quiet=False)
2025-09-12 00:11:50,247 - util.py[DEBUG]: Read 2561 bytes from /proc/422/mountinfo
2025-09-12 00:11:50,248 - subp.py[DEBUG]: Running command ['growpart', '--dry-run', '/dev/mmcblk0', '2'] with allowed return codes [0] (shell=False, capture=True)
2025-09-12 00:11:50,389 - subp.py[DEBUG]: Running command ['growpart', '/dev/mmcblk0', '2'] with allowed return codes [0] (shell=False, capture=True)
2025-09-12 00:11:50,995 - util.py[DEBUG]: resize_devices took 0.754 seconds
2025-09-12 00:11:50,996 - cc_growpart.py[INFO]: '/' resized: changed (/dev/mmcblk0, 2) from 2558525440 to 15386263040
2025-09-12 00:11:50,996 - handlers.py[DEBUG]: finish: init-network/config-growpart: SUCCESS: config-growpart ran successfully
2025-09-12 00:11:50,996 - modules.py[DEBUG]: Running module resizefs (<module 'cloudinit.config.cc_resizefs' from '/usr/lib/python3/dist-packages/cloudinit/config/cc_resizefs.py'>) with frequency always
2025-09-12 00:11:50,997 - handlers.py[DEBUG]: start: init-network/config-resizefs: running config-resizefs with frequency always
2025-09-12 00:11:50,997 - helpers.py[DEBUG]: Running config-resizefs using lock (<cloudinit.helpers.DummyLock object at 0x75399370>)
2025-09-12 00:11:50,997 - util.py[DEBUG]: Reading from /proc/422/mountinfo (quiet=False)
2025-09-12 00:11:50,998 - util.py[DEBUG]: Read 2561 bytes from /proc/422/mountinfo
2025-09-12 00:11:50,998 - cc_resizefs.py[DEBUG]: resize_info: dev=/dev/mmcblk0p2 mnt_point=/ path=/
2025-09-12 00:11:50,999 - cc_resizefs.py[DEBUG]: Resizing / (ext4) using resize2fs /dev/mmcblk0p2
2025-09-12 00:11:50,999 - subp.py[DEBUG]: Running command ('resize2fs', '/dev/mmcblk0p2') with allowed return codes [0] (shell=False, capture=True)
2025-09-12 00:11:51,380 - util.py[DEBUG]: Resizing took 0.381 seconds
2025-09-12 00:11:51,380 - cc_resizefs.py[DEBUG]: Resized root filesystem (type=ext4, val=True)
2025-09-12 00:11:51,381 - handlers.py[DEBUG]: finish: init-network/config-resizefs: SUCCESS: config-resizefs ran successfully
2025-09-12 00:11:51,381 - modules.py[DEBUG]: Running module mounts (<module 'cloudinit.config.cc_mounts' from '/usr/lib/python3/dist-packages/cloudinit/config/cc_mounts.py'>) with frequency once-per-instance
2025-09-12 00:11:51,382 - handlers.py[DEBUG]: start: init-network/config-mounts: running config-mounts with frequency once-per-instance
2025-09-12 00:11:51,382 - util.py[DEBUG]: Writing to /var/lib/cloud/instances/iid-datasource-none/sem/config_mounts - wb: [644] 24 bytes
2025-09-12 00:11:51,384 - helpers.py[DEBUG]: Running config-mounts using lock (<FileLock using file '/var/lib/cloud/instances/iid-datasource-none/sem/config_mounts'>)
2025-09-12 00:11:51,384 - cc_mounts.py[DEBUG]: mounts configuration is []
2025-09-12 00:11:51,384 - util.py[DEBUG]: Reading from /etc/fstab (quiet=False)
2025-09-12 00:11:51,385 - util.py[DEBUG]: Read 216 bytes from /etc/fstab
2025-09-12 00:11:51,385 - cc_mounts.py[DEBUG]: Attempting to determine the real name of ephemeral0
2025-09-12 00:11:51,385 - cc_mounts.py[DEBUG]: changed default device ephemeral0 => None
2025-09-12 00:11:51,385 - cc_mounts.py[DEBUG]: Ignoring nonexistent default named mount ephemeral0
2025-09-12 00:11:51,385 - cc_mounts.py[DEBUG]: Attempting to determine the real name of swap
2025-09-12 00:11:51,386 - cc_mounts.py[DEBUG]: changed default device swap => None
2025-09-12 00:11:51,386 - cc_mounts.py[DEBUG]: Ignoring nonexistent default named mount swap
2025-09-12 00:11:51,386 - cc_mounts.py[DEBUG]: no need to setup swap
2025-09-12 00:11:51,386 - cc_mounts.py[DEBUG]: No modifications to fstab needed
2025-09-12 00:11:51,386 - handlers.py[DEBUG]: finish: init-network/config-mounts: SUCCESS: config-mounts ran successfully
2025-09-12 00:11:51,387 - modules.py[DEBUG]: Running module set_hostname (<module 'cloudinit.config.cc_set_hostname' from '/usr/lib/python3/dist-packages/cloudinit/config/cc_set_hostname.py'>) with frequency once-per-instance
2025-09-12 00:11:51,387 - handlers.py[DEBUG]: start: init-network/config-set_hostname: running config-set_hostname with frequency once-per-instance
2025-09-12 00:11:51,388 - util.py[DEBUG]: Writing to /var/lib/cloud/instances/iid-datasource-none/sem/config_set_hostname - wb: [644] 22 bytes
2025-09-12 00:11:51,390 - helpers.py[DEBUG]: Running config-set_hostname using lock (<FileLock using file '/var/lib/cloud/instances/iid-datasource-none/sem/config_set_hostname'>)
2025-09-12 00:11:51,390 - util.py[DEBUG]: Reading from /etc/hosts (quiet=False)
2025-09-12 00:11:51,390 - util.py[DEBUG]: Read 132 bytes from /etc/hosts
2025-09-12 00:11:51,390 - util.py[DEBUG]: Reading from /etc/hosts (quiet=False)
2025-09-12 00:11:51,391 - util.py[DEBUG]: Read 132 bytes from /etc/hosts
2025-09-12 00:11:51,391 - cc_set_hostname.py[DEBUG]: Setting the hostname to hdmi-tester (hdmi-tester)
2025-09-12 00:11:51,391 - util.py[DEBUG]: Reading from /etc/hostname (quiet=False)
2025-09-12 00:11:51,391 - util.py[DEBUG]: Read 12 bytes from /etc/hostname
2025-09-12 00:11:51,392 - util.py[DEBUG]: Writing to /etc/hostname - wb: [644] 12 bytes
2025-09-12 00:11:51,394 - __init__.py[DEBUG]: Non-persistently setting the system hostname to hdmi-tester
2025-09-12 00:11:51,394 - subp.py[DEBUG]: Running command ['hostname', 'hdmi-tester'] with allowed return codes [0] (shell=False, capture=True)
2025-09-12 00:11:51,402 - atomic_helper.py[DEBUG]: Atomically writing to file /var/lib/cloud/data/set-hostname (via temporary file /var/lib/cloud/data/tmpa8jdpxyq) - w: [644] 55 bytes/chars
2025-09-12 00:11:51,403 - handlers.py[DEBUG]: finish: init-network/config-set_hostname: SUCCESS: config-set_hostname ran successfully
2025-09-12 00:11:51,403 - modules.py[DEBUG]: Running module update_hostname (<module 'cloudinit.config.cc_update_hostname' from '/usr/lib/python3/dist-packages/cloudinit/config/cc_update_hostname.py'>) with frequency always
2025-09-12 00:11:51,404 - handlers.py[DEBUG]: start: init-network/config-update_hostname: running config-update_hostname with frequency always
2025-09-12 00:11:51,404 - helpers.py[DEBUG]: Running config-update_hostname using lock (<cloudinit.helpers.DummyLock object at 0x75310e50>)
2025-09-12 00:11:51,405 - util.py[DEBUG]: Reading from /etc/hosts (quiet=False)
2025-09-12 00:11:51,405 - util.py[DEBUG]: Read 132 bytes from /etc/hosts
2025-09-12 00:11:51,405 - util.py[DEBUG]: Reading from /etc/hosts (quiet=False)
2025-09-12 00:11:51,405 - util.py[DEBUG]: Read 132 bytes from /etc/hosts
2025-09-12 00:11:51,406 - cc_update_hostname.py[DEBUG]: Updating hostname to hdmi-tester (hdmi-tester)
2025-09-12 00:11:51,406 - util.py[DEBUG]: Reading from /etc/hostname (quiet=False)
2025-09-12 00:11:51,406 - util.py[DEBUG]: Read 12 bytes from /etc/hostname
2025-09-12 00:11:51,406 - __init__.py[DEBUG]: Attempting to update hostname to hdmi-tester in 1 files
2025-09-12 00:11:51,406 - util.py[DEBUG]: Reading from /var/lib/cloud/data/previous-hostname (quiet=False)
2025-09-12 00:11:51,407 - util.py[DEBUG]: Writing to /var/lib/cloud/data/previous-hostname - wb: [644] 12 bytes
2025-09-12 00:11:51,409 - handlers.py[DEBUG]: finish: init-network/config-update_hostname: SUCCESS: config-update_hostname ran successfully
2025-09-12 00:11:51,409 - modules.py[DEBUG]: Running module users-groups (<module 'cloudinit.config.cc_users_groups' from '/usr/lib/python3/dist-packages/cloudinit/config/cc_users_groups.py'>) with frequency once-per-instance
2025-09-12 00:11:51,410 - handlers.py[DEBUG]: start: init-network/config-users-groups: running config-users-groups with frequency once-per-instance
2025-09-12 00:11:51,410 - util.py[DEBUG]: Writing to /var/lib/cloud/instances/iid-datasource-none/sem/config_users_groups - wb: [644] 23 bytes
2025-09-12 00:11:51,412 - helpers.py[DEBUG]: Running config-users-groups using lock (<FileLock using file '/var/lib/cloud/instances/iid-datasource-none/sem/config_users_groups'>)
2025-09-12 00:11:51,413 - util.py[DEBUG]: Reading from /etc/os-release (quiet=True)
2025-09-12 00:11:51,413 - util.py[DEBUG]: Read 309 bytes from /etc/os-release
2025-09-12 00:11:51,415 - util.py[DEBUG]: Reading from /etc/system-image/channel.ini (quiet=True)
2025-09-12 00:11:51,415 - util.py[DEBUG]: Read 0 bytes from /etc/system-image/channel.ini
2025-09-12 00:11:51,416 - __init__.py[DEBUG]: Adding user debian
2025-09-12 00:11:51,416 - subp.py[DEBUG]: Running hidden command to protect sensitive input/output logstring: ['useradd', 'debian', '--comment', 'Debian', '--groups', 'adm,audio,cdrom,dialout,dip,floppy,netdev,plugdev,sudo,video', '--shell', '/bin/bash', '-m']
2025-09-12 00:11:51,602 - subp.py[DEBUG]: Running command ['passwd', '-l', 'debian'] with allowed return codes [0] (shell=False, capture=True)
2025-09-12 00:11:51,640 - util.py[DEBUG]: Reading from /etc/sudoers (quiet=False)
2025-09-12 00:11:51,643 - util.py[DEBUG]: Read 1714 bytes from /etc/sudoers
2025-09-12 00:11:51,646 - util.py[DEBUG]: Writing to /etc/sudoers.d/90-cloud-init-users - wb: [440] 124 bytes
2025-09-12 00:11:51,648 - handlers.py[DEBUG]: finish: init-network/config-users-groups: SUCCESS: config-users-groups ran successfully
2025-09-12 00:11:51,648 - modules.py[DEBUG]: Running module ssh (<module 'cloudinit.config.cc_ssh' from '/usr/lib/python3/dist-packages/cloudinit/config/cc_ssh.py'>) with frequency once-per-instance
2025-09-12 00:11:51,649 - handlers.py[DEBUG]: start: init-network/config-ssh: running config-ssh with frequency once-per-instance
2025-09-12 00:11:51,650 - util.py[DEBUG]: Writing to /var/lib/cloud/instances/iid-datasource-none/sem/config_ssh - wb: [644] 24 bytes
2025-09-12 00:11:51,651 - helpers.py[DEBUG]: Running config-ssh using lock (<FileLock using file '/var/lib/cloud/instances/iid-datasource-none/sem/config_ssh'>)
2025-09-12 00:11:51,655 - util.py[DEBUG]: Reading from /etc/ssh/sshd_config (quiet=False)
2025-09-12 00:11:51,656 - util.py[DEBUG]: Read 3223 bytes from /etc/ssh/sshd_config
2025-09-12 00:11:51,658 - util.py[DEBUG]: Changing the ownership of /home/debian/.ssh to 1001:1001
2025-09-12 00:11:51,659 - util.py[DEBUG]: Writing to /home/debian/.ssh/authorized_keys - wb: [600] 0 bytes
2025-09-12 00:11:51,661 - util.py[DEBUG]: Changing the ownership of /home/debian/.ssh/authorized_keys to 1001:1001
2025-09-12 00:11:51,661 - util.py[DEBUG]: Reading from /home/debian/.ssh/authorized_keys (quiet=False)
2025-09-12 00:11:51,662 - util.py[DEBUG]: Read 0 bytes from /home/debian/.ssh/authorized_keys
2025-09-12 00:11:51,663 - util.py[DEBUG]: Writing to /home/debian/.ssh/authorized_keys - wb: [600] 0 bytes
2025-09-12 00:11:51,665 - util.py[DEBUG]: Reading from /etc/ssh/sshd_config (quiet=False)
2025-09-12 00:11:51,665 - util.py[DEBUG]: Read 3223 bytes from /etc/ssh/sshd_config
2025-09-12 00:11:51,669 - util.py[DEBUG]: Writing to /root/.ssh/authorized_keys - wb: [600] 0 bytes
2025-09-12 00:11:51,671 - util.py[DEBUG]: Changing the ownership of /root/.ssh/authorized_keys to 0:0
2025-09-12 00:11:51,671 - util.py[DEBUG]: Reading from /root/.ssh/authorized_keys (quiet=False)
2025-09-12 00:11:51,671 - util.py[DEBUG]: Read 0 bytes from /root/.ssh/authorized_keys
2025-09-12 00:11:51,672 - util.py[DEBUG]: Writing to /root/.ssh/authorized_keys - wb: [600] 0 bytes
2025-09-12 00:11:51,674 - handlers.py[DEBUG]: finish: init-network/config-ssh: SUCCESS: config-ssh ran successfully
2025-09-12 00:11:51,674 - main.py[DEBUG]: Ran 9 modules with 0 failures
2025-09-12 00:11:51,675 - atomic_helper.py[DEBUG]: Atomically writing to file /var/lib/cloud/data/status.json (via temporary file /var/lib/cloud/data/tmppxv02w4q) - w: [644] 513 bytes/chars
2025-09-12 00:11:51,676 - util.py[DEBUG]: Reading from /proc/uptime (quiet=False)
2025-09-12 00:11:51,677 - util.py[DEBUG]: Read 12 bytes from /proc/uptime
2025-09-12 00:11:51,677 - util.py[DEBUG]: cloud-init mode 'init' took 3.013 seconds (3.01)
2025-09-12 00:11:51,677 - handlers.py[DEBUG]: finish: init-network: SUCCESS: searching for network datasources
2025-09-12 00:12:02,309 - util.py[DEBUG]: Cloud-init v. 22.4.2 running 'modules:config' at Fri, 12 Sep 2025 00:12:02 +0000. Up 28.38 seconds.
2025-09-12 00:12:02,315 - util.py[DEBUG]: Reading from /usr/lib/python3/dist-packages/cloudinit/config/schemas/schema-cloud-config-v1.json (quiet=False)
2025-09-12 00:12:02,316 - util.py[DEBUG]: Read 133834 bytes from /usr/lib/python3/dist-packages/cloudinit/config/schemas/schema-cloud-config-v1.json
2025-09-12 00:12:02,327 - util.py[DEBUG]: Reading from /usr/lib/python3/dist-packages/cloudinit/config/schemas/schema-cloud-config-v1.json (quiet=False)
2025-09-12 00:12:02,328 - util.py[DEBUG]: Read 133834 bytes from /usr/lib/python3/dist-packages/cloudinit/config/schemas/schema-cloud-config-v1.json
2025-09-12 00:12:02,336 - util.py[DEBUG]: Reading from /usr/lib/python3/dist-packages/cloudinit/config/schemas/schema-cloud-config-v1.json (quiet=False)
2025-09-12 00:12:02,338 - util.py[DEBUG]: Read 133834 bytes from /usr/lib/python3/dist-packages/cloudinit/config/schemas/schema-cloud-config-v1.json
2025-09-12 00:12:02,349 - util.py[DEBUG]: Reading from /usr/lib/python3/dist-packages/cloudinit/config/schemas/schema-cloud-config-v1.json (quiet=False)
2025-09-12 00:12:02,350 - util.py[DEBUG]: Read 133834 bytes from /usr/lib/python3/dist-packages/cloudinit/config/schemas/schema-cloud-config-v1.json
2025-09-12 00:12:02,362 - util.py[DEBUG]: Reading from /usr/lib/python3/dist-packages/cloudinit/config/schemas/schema-cloud-config-v1.json (quiet=False)
2025-09-12 00:12:02,363 - util.py[DEBUG]: Read 133834 bytes from /usr/lib/python3/dist-packages/cloudinit/config/schemas/schema-cloud-config-v1.json
2025-09-12 00:12:02,378 - util.py[DEBUG]: Reading from /usr/lib/python3/dist-packages/cloudinit/config/schemas/schema-cloud-config-v1.json (quiet=False)
2025-09-12 00:12:02,379 - util.py[DEBUG]: Read 133834 bytes from /usr/lib/python3/dist-packages/cloudinit/config/schemas/schema-cloud-config-v1.json
2025-09-12 00:12:02,392 - util.py[DEBUG]: Reading from /usr/lib/python3/dist-packages/cloudinit/config/schemas/schema-cloud-config-v1.json (quiet=False)
2025-09-12 00:12:02,393 - util.py[DEBUG]: Read 133834 bytes from /usr/lib/python3/dist-packages/cloudinit/config/schemas/schema-cloud-config-v1.json
2025-09-12 00:12:02,418 - util.py[DEBUG]: Reading from /usr/lib/python3/dist-packages/cloudinit/config/schemas/schema-cloud-config-v1.json (quiet=False)
2025-09-12 00:12:02,420 - util.py[DEBUG]: Read 133834 bytes from /usr/lib/python3/dist-packages/cloudinit/config/schemas/schema-cloud-config-v1.json
2025-09-12 00:12:02,437 - util.py[DEBUG]: Reading from /usr/lib/python3/dist-packages/cloudinit/config/schemas/schema-cloud-config-v1.json (quiet=False)
2025-09-12 00:12:02,438 - util.py[DEBUG]: Read 133834 bytes from /usr/lib/python3/dist-packages/cloudinit/config/schemas/schema-cloud-config-v1.json
2025-09-12 00:12:02,449 - util.py[DEBUG]: Reading from /usr/lib/python3/dist-packages/cloudinit/config/schemas/schema-cloud-config-v1.json (quiet=False)
2025-09-12 00:12:02,450 - util.py[DEBUG]: Read 133834 bytes from /usr/lib/python3/dist-packages/cloudinit/config/schemas/schema-cloud-config-v1.json
2025-09-12 00:12:02,458 - util.py[DEBUG]: Reading from /usr/lib/python3/dist-packages/cloudinit/config/schemas/schema-cloud-config-v1.json (quiet=False)
2025-09-12 00:12:02,460 - util.py[DEBUG]: Read 133834 bytes from /usr/lib/python3/dist-packages/cloudinit/config/schemas/schema-cloud-config-v1.json
2025-09-12 00:12:02,469 - util.py[DEBUG]: Reading from /usr/lib/python3/dist-packages/cloudinit/config/schemas/schema-cloud-config-v1.json (quiet=False)
2025-09-12 00:12:02,470 - util.py[DEBUG]: Read 133834 bytes from /usr/lib/python3/dist-packages/cloudinit/config/schemas/schema-cloud-config-v1.json
2025-09-12 00:12:02,481 - util.py[DEBUG]: Reading from /usr/lib/python3/dist-packages/cloudinit/config/schemas/schema-cloud-config-v1.json (quiet=False)
2025-09-12 00:12:02,482 - util.py[DEBUG]: Read 133834 bytes from /usr/lib/python3/dist-packages/cloudinit/config/schemas/schema-cloud-config-v1.json
2025-09-12 00:12:02,489 - stages.py[DEBUG]: Using distro class <class 'cloudinit.distros.debian.Distro'>
2025-09-12 00:12:02,497 - modules.py[INFO]: Skipping modules 'snap,keyboard,apt-pipelining,ntp,timezone,disable-ec2-metadata,runcmd' because no applicable config is provided.
2025-09-12 00:12:02,498 - modules.py[DEBUG]: Running module ssh-import-id (<module 'cloudinit.config.cc_ssh_import_id' from '/usr/lib/python3/dist-packages/cloudinit/config/cc_ssh_import_id.py'>) with frequency once-per-instance
2025-09-12 00:12:02,499 - handlers.py[DEBUG]: start: modules-config/config-ssh-import-id: running config-ssh-import-id with frequency once-per-instance
2025-09-12 00:12:02,500 - util.py[DEBUG]: Writing to /var/lib/cloud/instances/iid-datasource-none/sem/config_ssh_import_id - wb: [644] 24 bytes
2025-09-12 00:12:02,501 - helpers.py[DEBUG]: Running config-ssh-import-id using lock (<FileLock using file '/var/lib/cloud/instances/iid-datasource-none/sem/config_ssh_import_id'>)
2025-09-12 00:12:02,502 - cc_ssh_import_id.py[DEBUG]: Skipping module named ssh-import-id, no 'ssh_import_id' directives found.
2025-09-12 00:12:02,502 - handlers.py[DEBUG]: finish: modules-config/config-ssh-import-id: SUCCESS: config-ssh-import-id ran successfully
2025-09-12 00:12:02,502 - modules.py[DEBUG]: Running module locale (<module 'cloudinit.config.cc_locale' from '/usr/lib/python3/dist-packages/cloudinit/config/cc_locale.py'>) with frequency once-per-instance
2025-09-12 00:12:02,503 - handlers.py[DEBUG]: start: modules-config/config-locale: running config-locale with frequency once-per-instance
2025-09-12 00:12:02,504 - util.py[DEBUG]: Writing to /var/lib/cloud/instances/iid-datasource-none/sem/config_locale - wb: [644] 23 bytes
2025-09-12 00:12:02,505 - helpers.py[DEBUG]: Running config-locale using lock (<FileLock using file '/var/lib/cloud/instances/iid-datasource-none/sem/config_locale'>)
2025-09-12 00:12:02,506 - util.py[DEBUG]: Reading from /etc/default/locale (quiet=False)
2025-09-12 00:12:02,506 - util.py[DEBUG]: Read 52 bytes from /etc/default/locale
2025-09-12 00:12:02,507 - cc_locale.py[DEBUG]: Setting locale to en_GB.UTF-8
2025-09-12 00:12:02,507 - debian.py[DEBUG]: System has 'LANG=en_GB.UTF-8' requested 'en_GB.UTF-8', skipping regeneration.
2025-09-12 00:12:02,507 - handlers.py[DEBUG]: finish: modules-config/config-locale: SUCCESS: config-locale ran successfully
2025-09-12 00:12:02,507 - modules.py[DEBUG]: Running module set-passwords (<module 'cloudinit.config.cc_set_passwords' from '/usr/lib/python3/dist-packages/cloudinit/config/cc_set_passwords.py'>) with frequency once-per-instance
2025-09-12 00:12:02,508 - handlers.py[DEBUG]: start: modules-config/config-set-passwords: running config-set-passwords with frequency once-per-instance
2025-09-12 00:12:02,509 - util.py[DEBUG]: Writing to /var/lib/cloud/instances/iid-datasource-none/sem/config_set_passwords - wb: [644] 24 bytes
2025-09-12 00:12:02,510 - helpers.py[DEBUG]: Running config-set-passwords using lock (<FileLock using file '/var/lib/cloud/instances/iid-datasource-none/sem/config_set_passwords'>)
2025-09-12 00:12:02,511 - subp.py[DEBUG]: Running command ['systemctl', 'status', 'ssh'] with allowed return codes [0] (shell=False, capture=True)
2025-09-12 00:12:02,553 - cc_set_passwords.py[DEBUG]: Writing config 'ssh_pwauth: None'. SSH service 'ssh' will not be restarted because it is stopped.
2025-09-12 00:12:02,553 - cc_set_passwords.py[DEBUG]: Leaving SSH config 'PasswordAuthentication' unchanged. ssh_pwauth=None
2025-09-12 00:12:02,554 - handlers.py[DEBUG]: finish: modules-config/config-set-passwords: SUCCESS: config-set-passwords ran successfully
2025-09-12 00:12:02,554 - modules.py[DEBUG]: Running module grub-dpkg (<module 'cloudinit.config.cc_grub_dpkg' from '/usr/lib/python3/dist-packages/cloudinit/config/cc_grub_dpkg.py'>) with frequency once-per-instance
2025-09-12 00:12:02,555 - handlers.py[DEBUG]: start: modules-config/config-grub-dpkg: running config-grub-dpkg with frequency once-per-instance
2025-09-12 00:12:02,555 - util.py[DEBUG]: Writing to /var/lib/cloud/instances/iid-datasource-none/sem/config_grub_dpkg - wb: [644] 24 bytes
2025-09-12 00:12:02,557 - helpers.py[DEBUG]: Running config-grub-dpkg using lock (<FileLock using file '/var/lib/cloud/instances/iid-datasource-none/sem/config_grub_dpkg'>)
2025-09-12 00:12:02,557 - subp.py[DEBUG]: Running command ['grub-probe', '-t', 'disk', '/boot'] with allowed return codes [0] (shell=False, capture=True)
2025-09-12 00:12:02,559 - cc_grub_dpkg.py[DEBUG]: 'grub-probe' not found in $PATH
2025-09-12 00:12:02,560 - cc_grub_dpkg.py[DEBUG]: Setting grub debconf-set-selections with '','true'
2025-09-12 00:12:02,560 - subp.py[DEBUG]: Running command ['debconf-set-selections'] with allowed return codes [0] (shell=False, capture=True)
2025-09-12 00:12:04,372 - handlers.py[DEBUG]: finish: modules-config/config-grub-dpkg: SUCCESS: config-grub-dpkg ran successfully
2025-09-12 00:12:04,372 - modules.py[DEBUG]: Running module apt-configure (<module 'cloudinit.config.cc_apt_configure' from '/usr/lib/python3/dist-packages/cloudinit/config/cc_apt_configure.py'>) with frequency once-per-instance
2025-09-12 00:12:04,373 - handlers.py[DEBUG]: start: modules-config/config-apt-configure: running config-apt-configure with frequency once-per-instance
2025-09-12 00:12:04,374 - util.py[DEBUG]: Writing to /var/lib/cloud/instances/iid-datasource-none/sem/config_apt_configure - wb: [644] 24 bytes
2025-09-12 00:12:04,379 - helpers.py[DEBUG]: Running config-apt-configure using lock (<FileLock using file '/var/lib/cloud/instances/iid-datasource-none/sem/config_apt_configure'>)
2025-09-12 00:12:04,379 - cc_apt_configure.py[DEBUG]: debconf_selections was not set in config
2025-09-12 00:12:04,379 - cc_apt_configure.py[DEBUG]: handling apt config: {'preserve_sources_list': True}
2025-09-12 00:12:04,380 - subp.py[DEBUG]: Running command ['lsb_release', '--all'] with allowed return codes [0] (shell=False, capture=True)
2025-09-12 00:12:04,434 - subp.py[DEBUG]: Running command ['dpkg', '--print-architecture'] with allowed return codes [0] (shell=False, capture=True)
2025-09-12 00:12:04,439 - cc_apt_configure.py[DEBUG]: got primary mirror: None
2025-09-12 00:12:04,440 - cc_apt_configure.py[DEBUG]: got security mirror: None
2025-09-12 00:12:04,440 - subp.py[DEBUG]: Running command ['dpkg', '--print-architecture'] with allowed return codes [0] (shell=False, capture=True)
2025-09-12 00:12:04,445 - __init__.py[DEBUG]: filtered distro mirror info: {'primary': 'https://deb.debian.org/debian', 'security': 'https://deb.debian.org/debian-security'}
2025-09-12 00:12:04,446 - cc_apt_configure.py[DEBUG]: Apt Mirror info: {'primary': 'https://deb.debian.org/debian', 'security': 'https://deb.debian.org/debian-security', 'PRIMARY': 'https://deb.debian.org/debian', 'SECURITY': 'https://deb.debian.org/debian-security', 'MIRROR': 'https://deb.debian.org/debian'}
2025-09-12 00:12:04,449 - handlers.py[DEBUG]: finish: modules-config/config-apt-configure: SUCCESS: config-apt-configure ran successfully
2025-09-12 00:12:04,450 - modules.py[DEBUG]: Running module byobu (<module 'cloudinit.config.cc_byobu' from '/usr/lib/python3/dist-packages/cloudinit/config/cc_byobu.py'>) with frequency once-per-instance
2025-09-12 00:12:04,451 - handlers.py[DEBUG]: start: modules-config/config-byobu: running config-byobu with frequency once-per-instance
2025-09-12 00:12:04,451 - util.py[DEBUG]: Writing to /var/lib/cloud/instances/iid-datasource-none/sem/config_byobu - wb: [644] 24 bytes
2025-09-12 00:12:04,453 - helpers.py[DEBUG]: Running config-byobu using lock (<FileLock using file '/var/lib/cloud/instances/iid-datasource-none/sem/config_byobu'>)
2025-09-12 00:12:04,453 - cc_byobu.py[DEBUG]: Skipping module named byobu, no 'byobu' values found
2025-09-12 00:12:04,454 - handlers.py[DEBUG]: finish: modules-config/config-byobu: SUCCESS: config-byobu ran successfully
2025-09-12 00:12:04,454 - main.py[DEBUG]: Ran 6 modules with 0 failures
2025-09-12 00:12:04,455 - atomic_helper.py[DEBUG]: Atomically writing to file /var/lib/cloud/data/status.json (via temporary file /var/lib/cloud/data/tmpfc197gy0) - w: [644] 539 bytes/chars
2025-09-12 00:12:04,456 - util.py[DEBUG]: Reading from /proc/uptime (quiet=False)
2025-09-12 00:12:04,457 - util.py[DEBUG]: Read 12 bytes from /proc/uptime
2025-09-12 00:12:04,457 - util.py[DEBUG]: cloud-init mode 'modules' took 2.421 seconds (2.42)
2025-09-12 00:12:04,457 - handlers.py[DEBUG]: finish: modules-config: SUCCESS: running modules for config
